<?xml version="1.0" ?>

<robot name="octopus">

	<link name="link_home">

    <inertial>
        <mass value="40.000000" />
        <origin xyz="0 0 0" rpy="00 0" />
        <inertia ixx="0.248970" ixy="0.000000" ixz="0.000000" iyy="0.703230" iyz="0.001820" izz="0.772560" />
      </inertial>
      <visual>
        <origin xyz="0 0 0" rpy="0 0 0" />
        <geometry>
           <box size=".7 0.4 0.3"/>
        </geometry>
      </visual>
    <collision>
            <origin xyz="0 0 0" rpy="0 0 0"/>
            <geometry>
                    <box size=".7 0.4 0.3"/>
            </geometry>
    </collision>
  </link>


  <link name="link_1">
    <inertial>
      <mass value="1"/>
      <origin xyz="0 0 -0.5" rpy="0 0 0" />
      <inertia ixx="0.1" ixy="0.0." ixz="0.0" iyy="0.1" iyz="0.0." izz="0.1"/>
    </inertial> 

    <visual>
      <origin xyz="0 0 -0.5" rpy="0 0 0"/>
      <geometry>
              <cylinder length="0.6" radius="0.2"/>
      </geometry>
    </visual>

    <collision>
      <origin xyz="0 0 -0.5" rpy="0 0 0"/>
      <geometry>
              <cylinder length="0.6" radius="0.2"/>
      </geometry>
    </collision>
		
		
  </link>

	<joint name="joint_1" type="continuous">
		<parent link="link_home"/>
		<child link="link_1"/>
		<origin xyz="0 0 -.15" rpy="0 0 0"/>
		<axis xyz="1 0 0"/>
    <!-- <limit effort="10.0" velocity="1"/> -->
		<dynamics damping="0.1" friction="0.1"/>
	</joint>
</robot>


