#octopus urdf file

<robot name="octopus">

	<!--
	 <link name="world"/>
	</link>
	-->
	
	<link name="link_home">
		<collision>
			<origin xyz="0 0 4" rpy="0 0 0"/>
			<geometry>
				<cylinder length="0.6" radius="0.2"/>
			</geometry>
		</collision>
	</link>
	
	<link name="link_1">
		
		<collision>
			<origin xyz="0 0 1" rpy="0 0 0"/>
			<geometry>
				<cylinder length="0.6" radius="0.2"/>
			</geometry>
		</collision>
	</link>
	
	####joint connecting to base and first link
	<joint>
		<parent link=""/>
		<child link=""/>
		<origin xyz=""/>
		<axis xyz=""/>
	</joint>

	<joint name="home_joint" type="continuous">
		
		<parent link="link_home"/>
		<child link="link_1"/>
		<origin xyz="0 0 3" rpy="0 0 0"/>
		<axis xyz="0 1 0"/>
	</joint>

</robot>


