<?xml version="0.0" ?>

<robot name="octopus">
	<!--
	<link name="world_plane_link">
  		<contact>
      			<lateral_friction value="1"/>
  		</contact>
    	
		<inertial>
      			<origin rpy="0 0 0" xyz="0 0 0"/>
       			<mass value=".0"/>
       			<inertia ixx="0" ixy="0" ixz="0" iyy="0" iyz="0" izz="0"/>
    		</inertial>
    	
		<visual>
      			<origin rpy="0 0 0" xyz="0 0 0"/>
      			<geometry>
				<mesh filename="plane.obj" scale="1 1 1"/>
      			</geometry>
       			<material name="white">
        			<color rgba="1 1 1 1"/>
      			</material>
    		</visual>
    	
		<collision>
      			<origin rpy="0 0 0" xyz="0 0 -5"/>
      			<geometry>
                		<box size="30 30 10"/>
      			</geometry>
    		</collision>
  	</link>
	-->

	<link name="link_home">
                <collision>
                        <origin xyz="0 0 4" rpy="0 0 0"/>
                        <geometry>
                                <cylinder length="0.6" radius="0.2"/>
                        </geometry>
                </collision>
        </link>


        <link name="link_1">

                <collision>
                        <origin xyz="0 0 -0.5" rpy="0 0 0"/>
                        <geometry>
                                <cylinder length="0.6" radius="0.2"/>
                        </geometry>
                </collision>
		<inertial>
			<mass value="1"/>
			<inertia ixx="0.1." ixy="0.0." ixz="0.0" iyy="0.1" iyz="0.0." izz="0.1"/>
		</inertial>	
		
        </link>



	<!--
	<joint name="home_joint" type="fixed">
		<parent link="world_plane_link"/>
		<child link="link_home"/>
		<origin xyz="0 0 0.01" rpy="0 0 0"/>
		
	</joint>
	-->
	
	<joint name="joint_1" type="continuous">
		<parent link="link_home"/>
		<child link="link_1"/>
		<origin xyz="0 0 3.5" rpy="0 0 0"/>
		<axis xyz="1 0 0"/>
		<dynamics damping="0" friction="0."/>
	</joint>
</robot>

<!--
<robot name="other_robot">
	<link name="ball">
                <collision>
                        <origin xyz="0 0 3" rpy="0 0 0"/>
                        <geometry>
                                <sphere radius="0.9"/>
                        </geometry>
                </collision>
		<visual>
			<origin xyz="0 0 3" rpy="0 0 0"/>
                        <geometry>
                                <sphere radius="0.9"/>
                        </geometry>
		</visual>
        </link>
</robot>
-->
