<robot name="plane">
  <link name="link_0">
  <contact>
      <lateral_friction value="1" />
  </contact>
    <inertial>
      <origin rpy="0 0 0" xyz="0 0 0" />
       <mass value=".0" />
       <inertia ixx="0" ixy="0" ixz="0" iyy="0" iyz="0" izz="0" />
    </inertial>
    <visual>
      <origin rpy="0 0 0" xyz="0 0 0" />
      <geometry>
          <mesh filename="plane.obj" scale="1 1 1" />
      </geometry>
       <material name="white">
        <color rgba="1 1 1 1" />
      </material>
    </visual>
    <collision>
      <origin rpy="0 0 0" xyz="0 0 -5" />
      <geometry>
                <box size="30 30 10" />
      </geometry>
    </collision>
  </link>




<link name="link_1"><collision><geometry><cylinder length="0.6" radius="0.2" /></geometry><origin xyz="0 0 1" /></collision></link><link name="link_2"><collision><geometry><cylinder length="0.6" radius="0.2" /></geometry><origin xyz="0 0 1" /></collision></link><link name="link_3"><collision><geometry><cylinder length="0.6" radius="0.2" /></geometry><origin xyz="0 0 1" /></collision></link><link name="link_4"><collision><geometry><cylinder length="0.6" radius="0.2" /></geometry><origin xyz="0 0 1" /></collision></link><link name="link_5"><collision><geometry><cylinder length="0.6" radius="0.2" /></geometry><origin xyz="0 0 1" /></collision></link><link name="link_6"><collision><geometry><cylinder length="0.6" radius="0.2" /></geometry><origin xyz="0 0 1" /></collision></link><link name="link_7"><collision><geometry><cylinder length="0.6" radius="0.2" /></geometry><origin xyz="0 0 1" /></collision></link><link name="link_8"><collision><geometry><cylinder length="0.6" radius="0.2" /></geometry><origin xyz="0 0 1" /></collision></link><link name="link_9"><collision><geometry><cylinder length="0.6" radius="0.2" /></geometry><origin xyz="0 0 1" /></collision></link><link name="link_10"><collision><geometry><cylinder length="0.6" radius="0.2" /></geometry><origin xyz="0 0 1" /></collision></link><link name="link_11"><collision><geometry><cylinder length="0.6" radius="0.2" /></geometry><origin xyz="0 0 1" /></collision></link><link name="link_12"><collision><geometry><cylinder length="0.6" radius="0.2" /></geometry><origin xyz="0 0 1" /></collision></link><link name="link_13"><collision><geometry><cylinder length="0.6" radius="0.2" /></geometry><origin xyz="0 0 1" /></collision></link><link name="link_14"><collision><geometry><cylinder length="0.6" radius="0.2" /></geometry><origin xyz="0 0 1" /></collision></link><link name="link_15"><collision><geometry><cylinder length="0.6" radius="0.2" /></geometry><origin xyz="0 0 1" /></collision></link><link name="link_16"><collision><geometry><cylinder length="0.6" radius="0.2" /></geometry><origin xyz="0 0 1" /></collision></link><link name="link_17"><collision><geometry><cylinder length="0.6" radius="0.2" /></geometry><origin xyz="0 0 1" /></collision></link><link name="link_18"><collision><geometry><cylinder length="0.6" radius="0.2" /></geometry><origin xyz="0 0 1" /></collision></link><link name="link_19"><collision><geometry><cylinder length="0.6" radius="0.2" /></geometry><origin xyz="0 0 1" /></collision></link><link name="link_20"><collision><geometry><cylinder length="0.6" radius="0.2" /></geometry><origin xyz="0 0 1" /></collision></link><link name="link_21"><collision><geometry><cylinder length="0.6" radius="0.2" /></geometry><origin xyz="0 0 1" /></collision></link><link name="link_22"><collision><geometry><cylinder length="0.6" radius="0.2" /></geometry><origin xyz="0 0 1" /></collision></link><link name="link_23"><collision><geometry><cylinder length="0.6" radius="0.2" /></geometry><origin xyz="0 0 1" /></collision></link><link name="link_24"><collision><geometry><cylinder length="0.6" radius="0.2" /></geometry><origin xyz="0 0 1" /></collision></link><link name="link_25"><collision><geometry><cylinder length="0.6" radius="0.2" /></geometry><origin xyz="0 0 1" /></collision></link><link name="link_26"><collision><geometry><cylinder length="0.6" radius="0.2" /></geometry><origin xyz="0 0 1" /></collision></link><link name="link_27"><collision><geometry><cylinder length="0.6" radius="0.2" /></geometry><origin xyz="0 0 1" /></collision></link><link name="link_28"><collision><geometry><cylinder length="0.6" radius="0.2" /></geometry><origin xyz="0 0 1" /></collision></link><link name="link_29"><collision><geometry><cylinder length="0.6" radius="0.2" /></geometry><origin xyz="0 0 1" /></collision></link><link name="link_30"><collision><geometry><cylinder length="0.6" radius="0.2" /></geometry><origin xyz="0 0 1" /></collision></link><link name="link_31"><collision><geometry><cylinder length="0.6" radius="0.2" /></geometry><origin xyz="0 0 1" /></collision></link><link name="link_32"><collision><geometry><cylinder length="0.6" radius="0.2" /></geometry><origin xyz="0 0 1" /></collision></link><joint name="link_0_to_link_1" type="continuous"><parent link="link_0" /><child link="link_1" /><origin xyz="0 0 2" /><xyz xyz="1 0 0" /></joint><joint name="link_1_to_link_2" type="continuous"><parent link="link_1" /><child link="link_2" /><origin xyz="0 0 2" /><xyz xyz="1 0 0" /></joint><joint name="link_2_to_link_3" type="continuous"><parent link="link_2" /><child link="link_3" /><origin xyz="0 0 2" /><xyz xyz="1 0 0" /></joint><joint name="link_3_to_link_4" type="continuous"><parent link="link_3" /><child link="link_4" /><origin xyz="0 0 2" /><xyz xyz="1 0 0" /></joint><joint name="link_4_to_link_5" type="continuous"><parent link="link_4" /><child link="link_5" /><origin xyz="0 0 2" /><xyz xyz="1 0 0" /></joint><joint name="link_5_to_link_6" type="continuous"><parent link="link_5" /><child link="link_6" /><origin xyz="0 0 2" /><xyz xyz="1 0 0" /></joint><joint name="link_6_to_link_7" type="continuous"><parent link="link_6" /><child link="link_7" /><origin xyz="0 0 2" /><xyz xyz="1 0 0" /></joint><joint name="link_7_to_link_8" type="continuous"><parent link="link_7" /><child link="link_8" /><origin xyz="0 0 2" /><xyz xyz="1 0 0" /></joint><joint name="link_8_to_link_9" type="continuous"><parent link="link_8" /><child link="link_9" /><origin xyz="0 0 2" /><xyz xyz="1 0 0" /></joint><joint name="link_9_to_link_10" type="continuous"><parent link="link_9" /><child link="link_10" /><origin xyz="0 0 2" /><xyz xyz="1 0 0" /></joint><joint name="link_10_to_link_11" type="continuous"><parent link="link_10" /><child link="link_11" /><origin xyz="0 0 2" /><xyz xyz="1 0 0" /></joint><joint name="link_11_to_link_12" type="continuous"><parent link="link_11" /><child link="link_12" /><origin xyz="0 0 2" /><xyz xyz="1 0 0" /></joint><joint name="link_12_to_link_13" type="continuous"><parent link="link_12" /><child link="link_13" /><origin xyz="0 0 2" /><xyz xyz="1 0 0" /></joint><joint name="link_13_to_link_14" type="continuous"><parent link="link_13" /><child link="link_14" /><origin xyz="0 0 2" /><xyz xyz="1 0 0" /></joint><joint name="link_14_to_link_15" type="continuous"><parent link="link_14" /><child link="link_15" /><origin xyz="0 0 2" /><xyz xyz="1 0 0" /></joint><joint name="link_15_to_link_16" type="continuous"><parent link="link_15" /><child link="link_16" /><origin xyz="0 0 2" /><xyz xyz="1 0 0" /></joint><joint name="link_16_to_link_17" type="continuous"><parent link="link_16" /><child link="link_17" /><origin xyz="0 0 2" /><xyz xyz="1 0 0" /></joint><joint name="link_17_to_link_18" type="continuous"><parent link="link_17" /><child link="link_18" /><origin xyz="0 0 2" /><xyz xyz="1 0 0" /></joint><joint name="link_18_to_link_19" type="continuous"><parent link="link_18" /><child link="link_19" /><origin xyz="0 0 2" /><xyz xyz="1 0 0" /></joint><joint name="link_19_to_link_20" type="continuous"><parent link="link_19" /><child link="link_20" /><origin xyz="0 0 2" /><xyz xyz="1 0 0" /></joint><joint name="link_20_to_link_21" type="continuous"><parent link="link_20" /><child link="link_21" /><origin xyz="0 0 2" /><xyz xyz="1 0 0" /></joint><joint name="link_21_to_link_22" type="continuous"><parent link="link_21" /><child link="link_22" /><origin xyz="0 0 2" /><xyz xyz="1 0 0" /></joint><joint name="link_22_to_link_23" type="continuous"><parent link="link_22" /><child link="link_23" /><origin xyz="0 0 2" /><xyz xyz="1 0 0" /></joint><joint name="link_23_to_link_24" type="continuous"><parent link="link_23" /><child link="link_24" /><origin xyz="0 0 2" /><xyz xyz="1 0 0" /></joint><joint name="link_24_to_link_25" type="continuous"><parent link="link_24" /><child link="link_25" /><origin xyz="0 0 2" /><xyz xyz="1 0 0" /></joint><joint name="link_25_to_link_26" type="continuous"><parent link="link_25" /><child link="link_26" /><origin xyz="0 0 2" /><xyz xyz="1 0 0" /></joint><joint name="link_26_to_link_27" type="continuous"><parent link="link_26" /><child link="link_27" /><origin xyz="0 0 2" /><xyz xyz="1 0 0" /></joint><joint name="link_27_to_link_28" type="continuous"><parent link="link_27" /><child link="link_28" /><origin xyz="0 0 2" /><xyz xyz="1 0 0" /></joint><joint name="link_28_to_link_29" type="continuous"><parent link="link_28" /><child link="link_29" /><origin xyz="0 0 2" /><xyz xyz="1 0 0" /></joint><joint name="link_29_to_link_30" type="continuous"><parent link="link_29" /><child link="link_30" /><origin xyz="0 0 2" /><xyz xyz="1 0 0" /></joint><joint name="link_30_to_link_31" type="continuous"><parent link="link_30" /><child link="link_31" /><origin xyz="0 0 2" /><xyz xyz="1 0 0" /></joint><joint name="link_31_to_link_32" type="continuous"><parent link="link_31" /><child link="link_32" /><origin xyz="0 0 2" /><xyz xyz="1 0 0" /></joint></robot>