<robot name="plane">
  <link name="link_0">
  <contact>
      <lateral_friction value="1" />
  </contact>
    <inertial>
      <origin rpy="0 0 0" xyz="0 0 0" />
       <mass value=".0" />
       <inertia ixx="0" ixy="0" ixz="0" iyy="0" iyz="0" izz="0" />
    </inertial>
    <visual>
      <origin rpy="0 0 0" xyz="0 0 0" />
      <geometry>
          <mesh filename="plane.obj" scale="1 1 1" />
      </geometry>
       <material name="white">
        <color rgba="1 1 1 1" />
      </material>
    </visual>
    <collision>
      <origin rpy="0 0 0" xyz="0 0 -5" />
      <geometry>
                <box size="30 30 10" />
      </geometry>
    </collision>
  </link>




<link name="link_1"><collision><geometry><cylinder length="0.6" radius="0.2" /></geometry><origin xyz="0 0 1" /></collision></link><link name="link_2"><collision><geometry><cylinder length="0.6" radius="0.2" /></geometry><origin xyz="0 0 1" /></collision></link><link name="link_3"><collision><geometry><cylinder length="0.6" radius="0.2" /></geometry><origin xyz="0 0 1" /></collision></link><link name="link_4"><collision><geometry><cylinder length="0.6" radius="0.2" /></geometry><origin xyz="0 0 1" /></collision></link><link name="link_5"><collision><geometry><cylinder length="0.6" radius="0.2" /></geometry><origin xyz="0 0 1" /></collision></link><link name="link_6"><collision><geometry><cylinder length="0.6" radius="0.2" /></geometry><origin xyz="0 0 1" /></collision></link><link name="link_7"><collision><geometry><cylinder length="0.6" radius="0.2" /></geometry><origin xyz="0 0 1" /></collision></link><link name="link_8"><collision><geometry><cylinder length="0.6" radius="0.2" /></geometry><origin xyz="0 0 1" /></collision></link><link name="link_9"><collision><geometry><cylinder length="0.6" radius="0.2" /></geometry><origin xyz="0 0 1" /></collision></link><link name="link_10"><collision><geometry><cylinder length="0.6" radius="0.2" /></geometry><origin xyz="0 0 1" /></collision></link><link name="link_11"><collision><geometry><cylinder length="0.6" radius="0.2" /></geometry><origin xyz="0 0 1" /></collision></link><link name="link_12"><collision><geometry><cylinder length="0.6" radius="0.2" /></geometry><origin xyz="0 0 1" /></collision></link><link name="link_13"><collision><geometry><cylinder length="0.6" radius="0.2" /></geometry><origin xyz="0 0 1" /></collision></link><link name="link_14"><collision><geometry><cylinder length="0.6" radius="0.2" /></geometry><origin xyz="0 0 1" /></collision></link><link name="link_15"><collision><geometry><cylinder length="0.6" radius="0.2" /></geometry><origin xyz="0 0 1" /></collision></link><link name="link_16"><collision><geometry><cylinder length="0.6" radius="0.2" /></geometry><origin xyz="0 0 1" /></collision></link><link name="link_17"><collision><geometry><cylinder length="0.6" radius="0.2" /></geometry><origin xyz="0 0 1" /></collision></link><link name="link_18"><collision><geometry><cylinder length="0.6" radius="0.2" /></geometry><origin xyz="0 0 1" /></collision></link><link name="link_19"><collision><geometry><cylinder length="0.6" radius="0.2" /></geometry><origin xyz="0 0 1" /></collision></link><link name="link_20"><collision><geometry><cylinder length="0.6" radius="0.2" /></geometry><origin xyz="0 0 1" /></collision></link><link name="link_21"><collision><geometry><cylinder length="0.6" radius="0.2" /></geometry><origin xyz="0 0 1" /></collision></link><link name="link_22"><collision><geometry><cylinder length="0.6" radius="0.2" /></geometry><origin xyz="0 0 1" /></collision></link><link name="link_23"><collision><geometry><cylinder length="0.6" radius="0.2" /></geometry><origin xyz="0 0 1" /></collision></link><link name="link_24"><collision><geometry><cylinder length="0.6" radius="0.2" /></geometry><origin xyz="0 0 1" /></collision></link><link name="link_25"><collision><geometry><cylinder length="0.6" radius="0.2" /></geometry><origin xyz="0 0 1" /></collision></link><link name="link_26"><collision><geometry><cylinder length="0.6" radius="0.2" /></geometry><origin xyz="0 0 1" /></collision></link><link name="link_27"><collision><geometry><cylinder length="0.6" radius="0.2" /></geometry><origin xyz="0 0 1" /></collision></link><link name="link_28"><collision><geometry><cylinder length="0.6" radius="0.2" /></geometry><origin xyz="0 0 1" /></collision></link><link name="link_29"><collision><geometry><cylinder length="0.6" radius="0.2" /></geometry><origin xyz="0 0 1" /></collision></link><link name="link_30"><collision><geometry><cylinder length="0.6" radius="0.2" /></geometry><origin xyz="0 0 1" /></collision></link><link name="link_31"><collision><geometry><cylinder length="0.6" radius="0.2" /></geometry><origin xyz="0 0 1" /></collision></link><link name="link_32"><collision><geometry><cylinder length="0.6" radius="0.2" /></geometry><origin xyz="0 0 1" /></collision></link><link name="link_33"><collision><geometry><cylinder length="0.6" radius="0.2" /></geometry><origin xyz="0 0 1" /></collision></link><link name="link_34"><collision><geometry><cylinder length="0.6" radius="0.2" /></geometry><origin xyz="0 0 1" /></collision></link><link name="link_35"><collision><geometry><cylinder length="0.6" radius="0.2" /></geometry><origin xyz="0 0 1" /></collision></link><link name="link_36"><collision><geometry><cylinder length="0.6" radius="0.2" /></geometry><origin xyz="0 0 1" /></collision></link><link name="link_37"><collision><geometry><cylinder length="0.6" radius="0.2" /></geometry><origin xyz="0 0 1" /></collision></link><link name="link_38"><collision><geometry><cylinder length="0.6" radius="0.2" /></geometry><origin xyz="0 0 1" /></collision></link><link name="link_39"><collision><geometry><cylinder length="0.6" radius="0.2" /></geometry><origin xyz="0 0 1" /></collision></link><link name="link_40"><collision><geometry><cylinder length="0.6" radius="0.2" /></geometry><origin xyz="0 0 1" /></collision></link><link name="link_41"><collision><geometry><cylinder length="0.6" radius="0.2" /></geometry><origin xyz="0 0 1" /></collision></link><link name="link_42"><collision><geometry><cylinder length="0.6" radius="0.2" /></geometry><origin xyz="0 0 1" /></collision></link><link name="link_43"><collision><geometry><cylinder length="0.6" radius="0.2" /></geometry><origin xyz="0 0 1" /></collision></link><link name="link_44"><collision><geometry><cylinder length="0.6" radius="0.2" /></geometry><origin xyz="0 0 1" /></collision></link><link name="link_45"><collision><geometry><cylinder length="0.6" radius="0.2" /></geometry><origin xyz="0 0 1" /></collision></link><link name="link_46"><collision><geometry><cylinder length="0.6" radius="0.2" /></geometry><origin xyz="0 0 1" /></collision></link><link name="link_47"><collision><geometry><cylinder length="0.6" radius="0.2" /></geometry><origin xyz="0 0 1" /></collision></link><link name="link_48"><collision><geometry><cylinder length="0.6" radius="0.2" /></geometry><origin xyz="0 0 1" /></collision></link><link name="link_49"><collision><geometry><cylinder length="0.6" radius="0.2" /></geometry><origin xyz="0 0 1" /></collision></link><link name="link_50"><collision><geometry><cylinder length="0.6" radius="0.2" /></geometry><origin xyz="0 0 1" /></collision></link><link name="link_51"><collision><geometry><cylinder length="0.6" radius="0.2" /></geometry><origin xyz="0 0 1" /></collision></link><link name="link_52"><collision><geometry><cylinder length="0.6" radius="0.2" /></geometry><origin xyz="0 0 1" /></collision></link><link name="link_53"><collision><geometry><cylinder length="0.6" radius="0.2" /></geometry><origin xyz="0 0 1" /></collision></link><link name="link_54"><collision><geometry><cylinder length="0.6" radius="0.2" /></geometry><origin xyz="0 0 1" /></collision></link><link name="link_55"><collision><geometry><cylinder length="0.6" radius="0.2" /></geometry><origin xyz="0 0 1" /></collision></link><link name="link_56"><collision><geometry><cylinder length="0.6" radius="0.2" /></geometry><origin xyz="0 0 1" /></collision></link><link name="link_57"><collision><geometry><cylinder length="0.6" radius="0.2" /></geometry><origin xyz="0 0 1" /></collision></link><link name="link_58"><collision><geometry><cylinder length="0.6" radius="0.2" /></geometry><origin xyz="0 0 1" /></collision></link><link name="link_59"><collision><geometry><cylinder length="0.6" radius="0.2" /></geometry><origin xyz="0 0 1" /></collision></link><link name="link_60"><collision><geometry><cylinder length="0.6" radius="0.2" /></geometry><origin xyz="0 0 1" /></collision></link><link name="link_61"><collision><geometry><cylinder length="0.6" radius="0.2" /></geometry><origin xyz="0 0 1" /></collision></link><link name="link_62"><collision><geometry><cylinder length="0.6" radius="0.2" /></geometry><origin xyz="0 0 1" /></collision></link><link name="link_63"><collision><geometry><cylinder length="0.6" radius="0.2" /></geometry><origin xyz="0 0 1" /></collision></link><link name="link_64"><collision><geometry><cylinder length="0.6" radius="0.2" /></geometry><origin xyz="0 0 1" /></collision></link><link name="link_65"><collision><geometry><cylinder length="0.6" radius="0.2" /></geometry><origin xyz="0 0 1" /></collision></link><link name="link_66"><collision><geometry><cylinder length="0.6" radius="0.2" /></geometry><origin xyz="0 0 1" /></collision></link><link name="link_67"><collision><geometry><cylinder length="0.6" radius="0.2" /></geometry><origin xyz="0 0 1" /></collision></link><link name="link_68"><collision><geometry><cylinder length="0.6" radius="0.2" /></geometry><origin xyz="0 0 1" /></collision></link><link name="link_69"><collision><geometry><cylinder length="0.6" radius="0.2" /></geometry><origin xyz="0 0 1" /></collision></link><link name="link_70"><collision><geometry><cylinder length="0.6" radius="0.2" /></geometry><origin xyz="0 0 1" /></collision></link><link name="link_71"><collision><geometry><cylinder length="0.6" radius="0.2" /></geometry><origin xyz="0 0 1" /></collision></link><link name="link_72"><collision><geometry><cylinder length="0.6" radius="0.2" /></geometry><origin xyz="0 0 1" /></collision></link><link name="link_73"><collision><geometry><cylinder length="0.6" radius="0.2" /></geometry><origin xyz="0 0 1" /></collision></link><link name="link_74"><collision><geometry><cylinder length="0.6" radius="0.2" /></geometry><origin xyz="0 0 1" /></collision></link><link name="link_75"><collision><geometry><cylinder length="0.6" radius="0.2" /></geometry><origin xyz="0 0 1" /></collision></link><link name="link_76"><collision><geometry><cylinder length="0.6" radius="0.2" /></geometry><origin xyz="0 0 1" /></collision></link><link name="link_77"><collision><geometry><cylinder length="0.6" radius="0.2" /></geometry><origin xyz="0 0 1" /></collision></link><link name="link_78"><collision><geometry><cylinder length="0.6" radius="0.2" /></geometry><origin xyz="0 0 1" /></collision></link><link name="link_79"><collision><geometry><cylinder length="0.6" radius="0.2" /></geometry><origin xyz="0 0 1" /></collision></link><link name="link_80"><collision><geometry><cylinder length="0.6" radius="0.2" /></geometry><origin xyz="0 0 1" /></collision></link><link name="link_81"><collision><geometry><cylinder length="0.6" radius="0.2" /></geometry><origin xyz="0 0 1" /></collision></link><link name="link_82"><collision><geometry><cylinder length="0.6" radius="0.2" /></geometry><origin xyz="0 0 1" /></collision></link><link name="link_83"><collision><geometry><cylinder length="0.6" radius="0.2" /></geometry><origin xyz="0 0 1" /></collision></link><link name="link_84"><collision><geometry><cylinder length="0.6" radius="0.2" /></geometry><origin xyz="0 0 1" /></collision></link><link name="link_85"><collision><geometry><cylinder length="0.6" radius="0.2" /></geometry><origin xyz="0 0 1" /></collision></link><link name="link_86"><collision><geometry><cylinder length="0.6" radius="0.2" /></geometry><origin xyz="0 0 1" /></collision></link><link name="link_87"><collision><geometry><cylinder length="0.6" radius="0.2" /></geometry><origin xyz="0 0 1" /></collision></link><link name="link_88"><collision><geometry><cylinder length="0.6" radius="0.2" /></geometry><origin xyz="0 0 1" /></collision></link><link name="link_89"><collision><geometry><cylinder length="0.6" radius="0.2" /></geometry><origin xyz="0 0 1" /></collision></link><link name="link_90"><collision><geometry><cylinder length="0.6" radius="0.2" /></geometry><origin xyz="0 0 1" /></collision></link><joint name="link_0_to_link_1" type="continuous"><parent link="link_0" /><child link="link_1" /><origin xyz="0 0 2" /><xyz xyz="1 0 0" /></joint><joint name="link_1_to_link_2" type="continuous"><parent link="link_1" /><child link="link_2" /><origin xyz="0 0 2" /><xyz xyz="1 0 0" /></joint><joint name="link_2_to_link_3" type="continuous"><parent link="link_2" /><child link="link_3" /><origin xyz="0 0 2" /><xyz xyz="1 0 0" /></joint><joint name="link_3_to_link_4" type="continuous"><parent link="link_3" /><child link="link_4" /><origin xyz="0 0 2" /><xyz xyz="1 0 0" /></joint><joint name="link_4_to_link_5" type="continuous"><parent link="link_4" /><child link="link_5" /><origin xyz="0 0 2" /><xyz xyz="1 0 0" /></joint><joint name="link_5_to_link_6" type="continuous"><parent link="link_5" /><child link="link_6" /><origin xyz="0 0 2" /><xyz xyz="1 0 0" /></joint><joint name="link_6_to_link_7" type="continuous"><parent link="link_6" /><child link="link_7" /><origin xyz="0 0 2" /><xyz xyz="1 0 0" /></joint><joint name="link_7_to_link_8" type="continuous"><parent link="link_7" /><child link="link_8" /><origin xyz="0 0 2" /><xyz xyz="1 0 0" /></joint><joint name="link_8_to_link_9" type="continuous"><parent link="link_8" /><child link="link_9" /><origin xyz="0 0 2" /><xyz xyz="1 0 0" /></joint><joint name="link_9_to_link_10" type="continuous"><parent link="link_9" /><child link="link_10" /><origin xyz="0 0 2" /><xyz xyz="1 0 0" /></joint><joint name="link_10_to_link_11" type="continuous"><parent link="link_10" /><child link="link_11" /><origin xyz="0 0 2" /><xyz xyz="1 0 0" /></joint><joint name="link_11_to_link_12" type="continuous"><parent link="link_11" /><child link="link_12" /><origin xyz="0 0 2" /><xyz xyz="1 0 0" /></joint><joint name="link_12_to_link_13" type="continuous"><parent link="link_12" /><child link="link_13" /><origin xyz="0 0 2" /><xyz xyz="1 0 0" /></joint><joint name="link_13_to_link_14" type="continuous"><parent link="link_13" /><child link="link_14" /><origin xyz="0 0 2" /><xyz xyz="1 0 0" /></joint><joint name="link_14_to_link_15" type="continuous"><parent link="link_14" /><child link="link_15" /><origin xyz="0 0 2" /><xyz xyz="1 0 0" /></joint><joint name="link_15_to_link_16" type="continuous"><parent link="link_15" /><child link="link_16" /><origin xyz="0 0 2" /><xyz xyz="1 0 0" /></joint><joint name="link_16_to_link_17" type="continuous"><parent link="link_16" /><child link="link_17" /><origin xyz="0 0 2" /><xyz xyz="1 0 0" /></joint><joint name="link_17_to_link_18" type="continuous"><parent link="link_17" /><child link="link_18" /><origin xyz="0 0 2" /><xyz xyz="1 0 0" /></joint><joint name="link_18_to_link_19" type="continuous"><parent link="link_18" /><child link="link_19" /><origin xyz="0 0 2" /><xyz xyz="1 0 0" /></joint><joint name="link_19_to_link_20" type="continuous"><parent link="link_19" /><child link="link_20" /><origin xyz="0 0 2" /><xyz xyz="1 0 0" /></joint><joint name="link_20_to_link_21" type="continuous"><parent link="link_20" /><child link="link_21" /><origin xyz="0 0 2" /><xyz xyz="1 0 0" /></joint><joint name="link_21_to_link_22" type="continuous"><parent link="link_21" /><child link="link_22" /><origin xyz="0 0 2" /><xyz xyz="1 0 0" /></joint><joint name="link_22_to_link_23" type="continuous"><parent link="link_22" /><child link="link_23" /><origin xyz="0 0 2" /><xyz xyz="1 0 0" /></joint><joint name="link_23_to_link_24" type="continuous"><parent link="link_23" /><child link="link_24" /><origin xyz="0 0 2" /><xyz xyz="1 0 0" /></joint><joint name="link_24_to_link_25" type="continuous"><parent link="link_24" /><child link="link_25" /><origin xyz="0 0 2" /><xyz xyz="1 0 0" /></joint><joint name="link_25_to_link_26" type="continuous"><parent link="link_25" /><child link="link_26" /><origin xyz="0 0 2" /><xyz xyz="1 0 0" /></joint><joint name="link_26_to_link_27" type="continuous"><parent link="link_26" /><child link="link_27" /><origin xyz="0 0 2" /><xyz xyz="1 0 0" /></joint><joint name="link_27_to_link_28" type="continuous"><parent link="link_27" /><child link="link_28" /><origin xyz="0 0 2" /><xyz xyz="1 0 0" /></joint><joint name="link_28_to_link_29" type="continuous"><parent link="link_28" /><child link="link_29" /><origin xyz="0 0 2" /><xyz xyz="1 0 0" /></joint><joint name="link_29_to_link_30" type="continuous"><parent link="link_29" /><child link="link_30" /><origin xyz="0 0 2" /><xyz xyz="1 0 0" /></joint><joint name="link_30_to_link_31" type="continuous"><parent link="link_30" /><child link="link_31" /><origin xyz="0 0 2" /><xyz xyz="1 0 0" /></joint><joint name="link_31_to_link_32" type="continuous"><parent link="link_31" /><child link="link_32" /><origin xyz="0 0 2" /><xyz xyz="1 0 0" /></joint><joint name="link_32_to_link_33" type="continuous"><parent link="link_32" /><child link="link_33" /><origin xyz="0 0 2" /><xyz xyz="1 0 0" /></joint><joint name="link_33_to_link_34" type="continuous"><parent link="link_33" /><child link="link_34" /><origin xyz="0 0 2" /><xyz xyz="1 0 0" /></joint><joint name="link_34_to_link_35" type="continuous"><parent link="link_34" /><child link="link_35" /><origin xyz="0 0 2" /><xyz xyz="1 0 0" /></joint><joint name="link_35_to_link_36" type="continuous"><parent link="link_35" /><child link="link_36" /><origin xyz="0 0 2" /><xyz xyz="1 0 0" /></joint><joint name="link_36_to_link_37" type="continuous"><parent link="link_36" /><child link="link_37" /><origin xyz="0 0 2" /><xyz xyz="1 0 0" /></joint><joint name="link_37_to_link_38" type="continuous"><parent link="link_37" /><child link="link_38" /><origin xyz="0 0 2" /><xyz xyz="1 0 0" /></joint><joint name="link_38_to_link_39" type="continuous"><parent link="link_38" /><child link="link_39" /><origin xyz="0 0 2" /><xyz xyz="1 0 0" /></joint><joint name="link_39_to_link_40" type="continuous"><parent link="link_39" /><child link="link_40" /><origin xyz="0 0 2" /><xyz xyz="1 0 0" /></joint><joint name="link_40_to_link_41" type="continuous"><parent link="link_40" /><child link="link_41" /><origin xyz="0 0 2" /><xyz xyz="1 0 0" /></joint><joint name="link_41_to_link_42" type="continuous"><parent link="link_41" /><child link="link_42" /><origin xyz="0 0 2" /><xyz xyz="1 0 0" /></joint><joint name="link_42_to_link_43" type="continuous"><parent link="link_42" /><child link="link_43" /><origin xyz="0 0 2" /><xyz xyz="1 0 0" /></joint><joint name="link_43_to_link_44" type="continuous"><parent link="link_43" /><child link="link_44" /><origin xyz="0 0 2" /><xyz xyz="1 0 0" /></joint><joint name="link_44_to_link_45" type="continuous"><parent link="link_44" /><child link="link_45" /><origin xyz="0 0 2" /><xyz xyz="1 0 0" /></joint><joint name="link_45_to_link_46" type="continuous"><parent link="link_45" /><child link="link_46" /><origin xyz="0 0 2" /><xyz xyz="1 0 0" /></joint><joint name="link_46_to_link_47" type="continuous"><parent link="link_46" /><child link="link_47" /><origin xyz="0 0 2" /><xyz xyz="1 0 0" /></joint><joint name="link_47_to_link_48" type="continuous"><parent link="link_47" /><child link="link_48" /><origin xyz="0 0 2" /><xyz xyz="1 0 0" /></joint><joint name="link_48_to_link_49" type="continuous"><parent link="link_48" /><child link="link_49" /><origin xyz="0 0 2" /><xyz xyz="1 0 0" /></joint><joint name="link_49_to_link_50" type="continuous"><parent link="link_49" /><child link="link_50" /><origin xyz="0 0 2" /><xyz xyz="1 0 0" /></joint><joint name="link_50_to_link_51" type="continuous"><parent link="link_50" /><child link="link_51" /><origin xyz="0 0 2" /><xyz xyz="1 0 0" /></joint><joint name="link_51_to_link_52" type="continuous"><parent link="link_51" /><child link="link_52" /><origin xyz="0 0 2" /><xyz xyz="1 0 0" /></joint><joint name="link_52_to_link_53" type="continuous"><parent link="link_52" /><child link="link_53" /><origin xyz="0 0 2" /><xyz xyz="1 0 0" /></joint><joint name="link_53_to_link_54" type="continuous"><parent link="link_53" /><child link="link_54" /><origin xyz="0 0 2" /><xyz xyz="1 0 0" /></joint><joint name="link_54_to_link_55" type="continuous"><parent link="link_54" /><child link="link_55" /><origin xyz="0 0 2" /><xyz xyz="1 0 0" /></joint><joint name="link_55_to_link_56" type="continuous"><parent link="link_55" /><child link="link_56" /><origin xyz="0 0 2" /><xyz xyz="1 0 0" /></joint><joint name="link_56_to_link_57" type="continuous"><parent link="link_56" /><child link="link_57" /><origin xyz="0 0 2" /><xyz xyz="1 0 0" /></joint><joint name="link_57_to_link_58" type="continuous"><parent link="link_57" /><child link="link_58" /><origin xyz="0 0 2" /><xyz xyz="1 0 0" /></joint><joint name="link_58_to_link_59" type="continuous"><parent link="link_58" /><child link="link_59" /><origin xyz="0 0 2" /><xyz xyz="1 0 0" /></joint><joint name="link_59_to_link_60" type="continuous"><parent link="link_59" /><child link="link_60" /><origin xyz="0 0 2" /><xyz xyz="1 0 0" /></joint><joint name="link_60_to_link_61" type="continuous"><parent link="link_60" /><child link="link_61" /><origin xyz="0 0 2" /><xyz xyz="1 0 0" /></joint><joint name="link_61_to_link_62" type="continuous"><parent link="link_61" /><child link="link_62" /><origin xyz="0 0 2" /><xyz xyz="1 0 0" /></joint><joint name="link_62_to_link_63" type="continuous"><parent link="link_62" /><child link="link_63" /><origin xyz="0 0 2" /><xyz xyz="1 0 0" /></joint><joint name="link_63_to_link_64" type="continuous"><parent link="link_63" /><child link="link_64" /><origin xyz="0 0 2" /><xyz xyz="1 0 0" /></joint><joint name="link_64_to_link_65" type="continuous"><parent link="link_64" /><child link="link_65" /><origin xyz="0 0 2" /><xyz xyz="1 0 0" /></joint><joint name="link_65_to_link_66" type="continuous"><parent link="link_65" /><child link="link_66" /><origin xyz="0 0 2" /><xyz xyz="1 0 0" /></joint><joint name="link_66_to_link_67" type="continuous"><parent link="link_66" /><child link="link_67" /><origin xyz="0 0 2" /><xyz xyz="1 0 0" /></joint><joint name="link_67_to_link_68" type="continuous"><parent link="link_67" /><child link="link_68" /><origin xyz="0 0 2" /><xyz xyz="1 0 0" /></joint><joint name="link_68_to_link_69" type="continuous"><parent link="link_68" /><child link="link_69" /><origin xyz="0 0 2" /><xyz xyz="1 0 0" /></joint><joint name="link_69_to_link_70" type="continuous"><parent link="link_69" /><child link="link_70" /><origin xyz="0 0 2" /><xyz xyz="1 0 0" /></joint><joint name="link_70_to_link_71" type="continuous"><parent link="link_70" /><child link="link_71" /><origin xyz="0 0 2" /><xyz xyz="1 0 0" /></joint><joint name="link_71_to_link_72" type="continuous"><parent link="link_71" /><child link="link_72" /><origin xyz="0 0 2" /><xyz xyz="1 0 0" /></joint><joint name="link_72_to_link_73" type="continuous"><parent link="link_72" /><child link="link_73" /><origin xyz="0 0 2" /><xyz xyz="1 0 0" /></joint><joint name="link_73_to_link_74" type="continuous"><parent link="link_73" /><child link="link_74" /><origin xyz="0 0 2" /><xyz xyz="1 0 0" /></joint><joint name="link_74_to_link_75" type="continuous"><parent link="link_74" /><child link="link_75" /><origin xyz="0 0 2" /><xyz xyz="1 0 0" /></joint><joint name="link_75_to_link_76" type="continuous"><parent link="link_75" /><child link="link_76" /><origin xyz="0 0 2" /><xyz xyz="1 0 0" /></joint><joint name="link_76_to_link_77" type="continuous"><parent link="link_76" /><child link="link_77" /><origin xyz="0 0 2" /><xyz xyz="1 0 0" /></joint><joint name="link_77_to_link_78" type="continuous"><parent link="link_77" /><child link="link_78" /><origin xyz="0 0 2" /><xyz xyz="1 0 0" /></joint><joint name="link_78_to_link_79" type="continuous"><parent link="link_78" /><child link="link_79" /><origin xyz="0 0 2" /><xyz xyz="1 0 0" /></joint><joint name="link_79_to_link_80" type="continuous"><parent link="link_79" /><child link="link_80" /><origin xyz="0 0 2" /><xyz xyz="1 0 0" /></joint><joint name="link_80_to_link_81" type="continuous"><parent link="link_80" /><child link="link_81" /><origin xyz="0 0 2" /><xyz xyz="1 0 0" /></joint><joint name="link_81_to_link_82" type="continuous"><parent link="link_81" /><child link="link_82" /><origin xyz="0 0 2" /><xyz xyz="1 0 0" /></joint><joint name="link_82_to_link_83" type="continuous"><parent link="link_82" /><child link="link_83" /><origin xyz="0 0 2" /><xyz xyz="1 0 0" /></joint><joint name="link_83_to_link_84" type="continuous"><parent link="link_83" /><child link="link_84" /><origin xyz="0 0 2" /><xyz xyz="1 0 0" /></joint><joint name="link_84_to_link_85" type="continuous"><parent link="link_84" /><child link="link_85" /><origin xyz="0 0 2" /><xyz xyz="1 0 0" /></joint><joint name="link_85_to_link_86" type="continuous"><parent link="link_85" /><child link="link_86" /><origin xyz="0 0 2" /><xyz xyz="1 0 0" /></joint><joint name="link_86_to_link_87" type="continuous"><parent link="link_86" /><child link="link_87" /><origin xyz="0 0 2" /><xyz xyz="1 0 0" /></joint><joint name="link_87_to_link_88" type="continuous"><parent link="link_87" /><child link="link_88" /><origin xyz="0 0 2" /><xyz xyz="1 0 0" /></joint><joint name="link_88_to_link_89" type="continuous"><parent link="link_88" /><child link="link_89" /><origin xyz="0 0 2" /><xyz xyz="1 0 0" /></joint><joint name="link_89_to_link_90" type="continuous"><parent link="link_89" /><child link="link_90" /><origin xyz="0 0 2" /><xyz xyz="1 0 0" /></joint></robot>