<robot name="plane">
  <link name="link_0">
  <contact>
      <lateral_friction value="1" />
  </contact>
    <inertial>
      <origin rpy="0 0 0" xyz="0 0 0" />
       <mass value=".0" />
       <inertia ixx="0" ixy="0" ixz="0" iyy="0" iyz="0" izz="0" />
    </inertial>
    <visual>
      <origin rpy="0 0 0" xyz="0 0 0" />
      <geometry>
          <mesh filename="plane.obj" scale="1 1 1" />
      </geometry>
       <material name="white">
        <color rgba="1 1 1 1" />
      </material>
    </visual>
    <collision>
      <origin rpy="0 0 0" xyz="0 0 -5" />
      <geometry>
                <box size="30 30 10" />
      </geometry>
    </collision>
  </link>




<link name="link_1"><collision><geometry><cylinder length="0.6" radius="0.2" /></geometry><origin xyz="0 0 1" /></collision></link><link name="link_2"><collision><geometry><cylinder length="0.6" radius="0.2" /></geometry><origin xyz="0 0 1" /></collision></link><link name="link_3"><collision><geometry><cylinder length="0.6" radius="0.2" /></geometry><origin xyz="0 0 1" /></collision></link><link name="link_4"><collision><geometry><cylinder length="0.6" radius="0.2" /></geometry><origin xyz="0 0 1" /></collision></link><link name="link_5"><collision><geometry><cylinder length="0.6" radius="0.2" /></geometry><origin xyz="0 0 1" /></collision></link><link name="link_6"><collision><geometry><cylinder length="0.6" radius="0.2" /></geometry><origin xyz="0 0 1" /></collision></link><link name="link_7"><collision><geometry><cylinder length="0.6" radius="0.2" /></geometry><origin xyz="0 0 1" /></collision></link><link name="link_8"><collision><geometry><cylinder length="0.6" radius="0.2" /></geometry><origin xyz="0 0 1" /></collision></link><link name="link_9"><collision><geometry><cylinder length="0.6" radius="0.2" /></geometry><origin xyz="0 0 1" /></collision></link><link name="link_10"><collision><geometry><cylinder length="0.6" radius="0.2" /></geometry><origin xyz="0 0 1" /></collision></link><link name="link_11"><collision><geometry><cylinder length="0.6" radius="0.2" /></geometry><origin xyz="0 0 1" /></collision></link><link name="link_12"><collision><geometry><cylinder length="0.6" radius="0.2" /></geometry><origin xyz="0 0 1" /></collision></link><link name="link_13"><collision><geometry><cylinder length="0.6" radius="0.2" /></geometry><origin xyz="0 0 1" /></collision></link><link name="link_14"><collision><geometry><cylinder length="0.6" radius="0.2" /></geometry><origin xyz="0 0 1" /></collision></link><link name="link_15"><collision><geometry><cylinder length="0.6" radius="0.2" /></geometry><origin xyz="0 0 1" /></collision></link><link name="link_16"><collision><geometry><cylinder length="0.6" radius="0.2" /></geometry><origin xyz="0 0 1" /></collision></link><link name="link_17"><collision><geometry><cylinder length="0.6" radius="0.2" /></geometry><origin xyz="0 0 1" /></collision></link><link name="link_18"><collision><geometry><cylinder length="0.6" radius="0.2" /></geometry><origin xyz="0 0 1" /></collision></link><link name="link_19"><collision><geometry><cylinder length="0.6" radius="0.2" /></geometry><origin xyz="0 0 1" /></collision></link><link name="link_20"><collision><geometry><cylinder length="0.6" radius="0.2" /></geometry><origin xyz="0 0 1" /></collision></link><link name="link_21"><collision><geometry><cylinder length="0.6" radius="0.2" /></geometry><origin xyz="0 0 1" /></collision></link><link name="link_22"><collision><geometry><cylinder length="0.6" radius="0.2" /></geometry><origin xyz="0 0 1" /></collision></link><link name="link_23"><collision><geometry><cylinder length="0.6" radius="0.2" /></geometry><origin xyz="0 0 1" /></collision></link><link name="link_24"><collision><geometry><cylinder length="0.6" radius="0.2" /></geometry><origin xyz="0 0 1" /></collision></link><link name="link_25"><collision><geometry><cylinder length="0.6" radius="0.2" /></geometry><origin xyz="0 0 1" /></collision></link><link name="link_26"><collision><geometry><cylinder length="0.6" radius="0.2" /></geometry><origin xyz="0 0 1" /></collision></link><link name="link_27"><collision><geometry><cylinder length="0.6" radius="0.2" /></geometry><origin xyz="0 0 1" /></collision></link><link name="link_28"><collision><geometry><cylinder length="0.6" radius="0.2" /></geometry><origin xyz="0 0 1" /></collision></link><link name="link_29"><collision><geometry><cylinder length="0.6" radius="0.2" /></geometry><origin xyz="0 0 1" /></collision></link><link name="link_30"><collision><geometry><cylinder length="0.6" radius="0.2" /></geometry><origin xyz="0 0 1" /></collision></link><link name="link_31"><collision><geometry><cylinder length="0.6" radius="0.2" /></geometry><origin xyz="0 0 1" /></collision></link><link name="link_32"><collision><geometry><cylinder length="0.6" radius="0.2" /></geometry><origin xyz="0 0 1" /></collision></link><link name="link_33"><collision><geometry><cylinder length="0.6" radius="0.2" /></geometry><origin xyz="0 0 1" /></collision></link><link name="link_34"><collision><geometry><cylinder length="0.6" radius="0.2" /></geometry><origin xyz="0 0 1" /></collision></link><link name="link_35"><collision><geometry><cylinder length="0.6" radius="0.2" /></geometry><origin xyz="0 0 1" /></collision></link><link name="link_36"><collision><geometry><cylinder length="0.6" radius="0.2" /></geometry><origin xyz="0 0 1" /></collision></link><link name="link_37"><collision><geometry><cylinder length="0.6" radius="0.2" /></geometry><origin xyz="0 0 1" /></collision></link><link name="link_38"><collision><geometry><cylinder length="0.6" radius="0.2" /></geometry><origin xyz="0 0 1" /></collision></link><link name="link_39"><collision><geometry><cylinder length="0.6" radius="0.2" /></geometry><origin xyz="0 0 1" /></collision></link><link name="link_40"><collision><geometry><cylinder length="0.6" radius="0.2" /></geometry><origin xyz="0 0 1" /></collision></link><link name="link_41"><collision><geometry><cylinder length="0.6" radius="0.2" /></geometry><origin xyz="0 0 1" /></collision></link><link name="link_42"><collision><geometry><cylinder length="0.6" radius="0.2" /></geometry><origin xyz="0 0 1" /></collision></link><link name="link_43"><collision><geometry><cylinder length="0.6" radius="0.2" /></geometry><origin xyz="0 0 1" /></collision></link><link name="link_44"><collision><geometry><cylinder length="0.6" radius="0.2" /></geometry><origin xyz="0 0 1" /></collision></link><link name="link_45"><collision><geometry><cylinder length="0.6" radius="0.2" /></geometry><origin xyz="0 0 1" /></collision></link><link name="link_46"><collision><geometry><cylinder length="0.6" radius="0.2" /></geometry><origin xyz="0 0 1" /></collision></link><link name="link_47"><collision><geometry><cylinder length="0.6" radius="0.2" /></geometry><origin xyz="0 0 1" /></collision></link><link name="link_48"><collision><geometry><cylinder length="0.6" radius="0.2" /></geometry><origin xyz="0 0 1" /></collision></link><link name="link_49"><collision><geometry><cylinder length="0.6" radius="0.2" /></geometry><origin xyz="0 0 1" /></collision></link><link name="link_50"><collision><geometry><cylinder length="0.6" radius="0.2" /></geometry><origin xyz="0 0 1" /></collision></link><link name="link_51"><collision><geometry><cylinder length="0.6" radius="0.2" /></geometry><origin xyz="0 0 1" /></collision></link><link name="link_52"><collision><geometry><cylinder length="0.6" radius="0.2" /></geometry><origin xyz="0 0 1" /></collision></link><link name="link_53"><collision><geometry><cylinder length="0.6" radius="0.2" /></geometry><origin xyz="0 0 1" /></collision></link><link name="link_54"><collision><geometry><cylinder length="0.6" radius="0.2" /></geometry><origin xyz="0 0 1" /></collision></link><link name="link_55"><collision><geometry><cylinder length="0.6" radius="0.2" /></geometry><origin xyz="0 0 1" /></collision></link><link name="link_56"><collision><geometry><cylinder length="0.6" radius="0.2" /></geometry><origin xyz="0 0 1" /></collision></link><link name="link_57"><collision><geometry><cylinder length="0.6" radius="0.2" /></geometry><origin xyz="0 0 1" /></collision></link><link name="link_58"><collision><geometry><cylinder length="0.6" radius="0.2" /></geometry><origin xyz="0 0 1" /></collision></link><link name="link_59"><collision><geometry><cylinder length="0.6" radius="0.2" /></geometry><origin xyz="0 0 1" /></collision></link><link name="link_60"><collision><geometry><cylinder length="0.6" radius="0.2" /></geometry><origin xyz="0 0 1" /></collision></link><link name="link_61"><collision><geometry><cylinder length="0.6" radius="0.2" /></geometry><origin xyz="0 0 1" /></collision></link><link name="link_62"><collision><geometry><cylinder length="0.6" radius="0.2" /></geometry><origin xyz="0 0 1" /></collision></link><link name="link_63"><collision><geometry><cylinder length="0.6" radius="0.2" /></geometry><origin xyz="0 0 1" /></collision></link><link name="link_64"><collision><geometry><cylinder length="0.6" radius="0.2" /></geometry><origin xyz="0 0 1" /></collision></link><link name="link_65"><collision><geometry><cylinder length="0.6" radius="0.2" /></geometry><origin xyz="0 0 1" /></collision></link><link name="link_66"><collision><geometry><cylinder length="0.6" radius="0.2" /></geometry><origin xyz="0 0 1" /></collision></link><link name="link_67"><collision><geometry><cylinder length="0.6" radius="0.2" /></geometry><origin xyz="0 0 1" /></collision></link><link name="link_68"><collision><geometry><cylinder length="0.6" radius="0.2" /></geometry><origin xyz="0 0 1" /></collision></link><link name="link_69"><collision><geometry><cylinder length="0.6" radius="0.2" /></geometry><origin xyz="0 0 1" /></collision></link><link name="link_70"><collision><geometry><cylinder length="0.6" radius="0.2" /></geometry><origin xyz="0 0 1" /></collision></link><link name="link_71"><collision><geometry><cylinder length="0.6" radius="0.2" /></geometry><origin xyz="0 0 1" /></collision></link><link name="link_72"><collision><geometry><cylinder length="0.6" radius="0.2" /></geometry><origin xyz="0 0 1" /></collision></link><link name="link_73"><collision><geometry><cylinder length="0.6" radius="0.2" /></geometry><origin xyz="0 0 1" /></collision></link><link name="link_74"><collision><geometry><cylinder length="0.6" radius="0.2" /></geometry><origin xyz="0 0 1" /></collision></link><link name="link_75"><collision><geometry><cylinder length="0.6" radius="0.2" /></geometry><origin xyz="0 0 1" /></collision></link><link name="link_76"><collision><geometry><cylinder length="0.6" radius="0.2" /></geometry><origin xyz="0 0 1" /></collision></link><link name="link_77"><collision><geometry><cylinder length="0.6" radius="0.2" /></geometry><origin xyz="0 0 1" /></collision></link><link name="link_78"><collision><geometry><cylinder length="0.6" radius="0.2" /></geometry><origin xyz="0 0 1" /></collision></link><link name="link_79"><collision><geometry><cylinder length="0.6" radius="0.2" /></geometry><origin xyz="0 0 1" /></collision></link><link name="link_80"><collision><geometry><cylinder length="0.6" radius="0.2" /></geometry><origin xyz="0 0 1" /></collision></link><link name="link_81"><collision><geometry><cylinder length="0.6" radius="0.2" /></geometry><origin xyz="0 0 1" /></collision></link><link name="link_82"><collision><geometry><cylinder length="0.6" radius="0.2" /></geometry><origin xyz="0 0 1" /></collision></link><link name="link_83"><collision><geometry><cylinder length="0.6" radius="0.2" /></geometry><origin xyz="0 0 1" /></collision></link><link name="link_84"><collision><geometry><cylinder length="0.6" radius="0.2" /></geometry><origin xyz="0 0 1" /></collision></link><link name="link_85"><collision><geometry><cylinder length="0.6" radius="0.2" /></geometry><origin xyz="0 0 1" /></collision></link><link name="link_86"><collision><geometry><cylinder length="0.6" radius="0.2" /></geometry><origin xyz="0 0 1" /></collision></link><link name="link_87"><collision><geometry><cylinder length="0.6" radius="0.2" /></geometry><origin xyz="0 0 1" /></collision></link><link name="link_88"><collision><geometry><cylinder length="0.6" radius="0.2" /></geometry><origin xyz="0 0 1" /></collision></link><link name="link_89"><collision><geometry><cylinder length="0.6" radius="0.2" /></geometry><origin xyz="0 0 1" /></collision></link><link name="link_90"><collision><geometry><cylinder length="0.6" radius="0.2" /></geometry><origin xyz="0 0 1" /></collision></link><link name="link_91"><collision><geometry><cylinder length="0.6" radius="0.2" /></geometry><origin xyz="0 0 1" /></collision></link><link name="link_92"><collision><geometry><cylinder length="0.6" radius="0.2" /></geometry><origin xyz="0 0 1" /></collision></link><link name="link_93"><collision><geometry><cylinder length="0.6" radius="0.2" /></geometry><origin xyz="0 0 1" /></collision></link><link name="link_94"><collision><geometry><cylinder length="0.6" radius="0.2" /></geometry><origin xyz="0 0 1" /></collision></link><link name="link_95"><collision><geometry><cylinder length="0.6" radius="0.2" /></geometry><origin xyz="0 0 1" /></collision></link><link name="link_96"><collision><geometry><cylinder length="0.6" radius="0.2" /></geometry><origin xyz="0 0 1" /></collision></link><link name="link_97"><collision><geometry><cylinder length="0.6" radius="0.2" /></geometry><origin xyz="0 0 1" /></collision></link><link name="link_98"><collision><geometry><cylinder length="0.6" radius="0.2" /></geometry><origin xyz="0 0 1" /></collision></link><link name="link_99"><collision><geometry><cylinder length="0.6" radius="0.2" /></geometry><origin xyz="0 0 1" /></collision></link><link name="link_100"><collision><geometry><cylinder length="0.6" radius="0.2" /></geometry><origin xyz="0 0 1" /></collision></link><link name="link_101"><collision><geometry><cylinder length="0.6" radius="0.2" /></geometry><origin xyz="0 0 1" /></collision></link><link name="link_102"><collision><geometry><cylinder length="0.6" radius="0.2" /></geometry><origin xyz="0 0 1" /></collision></link><link name="link_103"><collision><geometry><cylinder length="0.6" radius="0.2" /></geometry><origin xyz="0 0 1" /></collision></link><link name="link_104"><collision><geometry><cylinder length="0.6" radius="0.2" /></geometry><origin xyz="0 0 1" /></collision></link><link name="link_105"><collision><geometry><cylinder length="0.6" radius="0.2" /></geometry><origin xyz="0 0 1" /></collision></link><link name="link_106"><collision><geometry><cylinder length="0.6" radius="0.2" /></geometry><origin xyz="0 0 1" /></collision></link><link name="link_107"><collision><geometry><cylinder length="0.6" radius="0.2" /></geometry><origin xyz="0 0 1" /></collision></link><link name="link_108"><collision><geometry><cylinder length="0.6" radius="0.2" /></geometry><origin xyz="0 0 1" /></collision></link><link name="link_109"><collision><geometry><cylinder length="0.6" radius="0.2" /></geometry><origin xyz="0 0 1" /></collision></link><link name="link_110"><collision><geometry><cylinder length="0.6" radius="0.2" /></geometry><origin xyz="0 0 1" /></collision></link><link name="link_111"><collision><geometry><cylinder length="0.6" radius="0.2" /></geometry><origin xyz="0 0 1" /></collision></link><link name="link_112"><collision><geometry><cylinder length="0.6" radius="0.2" /></geometry><origin xyz="0 0 1" /></collision></link><link name="link_113"><collision><geometry><cylinder length="0.6" radius="0.2" /></geometry><origin xyz="0 0 1" /></collision></link><link name="link_114"><collision><geometry><cylinder length="0.6" radius="0.2" /></geometry><origin xyz="0 0 1" /></collision></link><link name="link_115"><collision><geometry><cylinder length="0.6" radius="0.2" /></geometry><origin xyz="0 0 1" /></collision></link><link name="link_116"><collision><geometry><cylinder length="0.6" radius="0.2" /></geometry><origin xyz="0 0 1" /></collision></link><link name="link_117"><collision><geometry><cylinder length="0.6" radius="0.2" /></geometry><origin xyz="0 0 1" /></collision></link><link name="link_118"><collision><geometry><cylinder length="0.6" radius="0.2" /></geometry><origin xyz="0 0 1" /></collision></link><link name="link_119"><collision><geometry><cylinder length="0.6" radius="0.2" /></geometry><origin xyz="0 0 1" /></collision></link><link name="link_120"><collision><geometry><cylinder length="0.6" radius="0.2" /></geometry><origin xyz="0 0 1" /></collision></link><link name="link_121"><collision><geometry><cylinder length="0.6" radius="0.2" /></geometry><origin xyz="0 0 1" /></collision></link><link name="link_122"><collision><geometry><cylinder length="0.6" radius="0.2" /></geometry><origin xyz="0 0 1" /></collision></link><link name="link_123"><collision><geometry><cylinder length="0.6" radius="0.2" /></geometry><origin xyz="0 0 1" /></collision></link><link name="link_124"><collision><geometry><cylinder length="0.6" radius="0.2" /></geometry><origin xyz="0 0 1" /></collision></link><link name="link_125"><collision><geometry><cylinder length="0.6" radius="0.2" /></geometry><origin xyz="0 0 1" /></collision></link><link name="link_126"><collision><geometry><cylinder length="0.6" radius="0.2" /></geometry><origin xyz="0 0 1" /></collision></link><link name="link_127"><collision><geometry><cylinder length="0.6" radius="0.2" /></geometry><origin xyz="0 0 1" /></collision></link><link name="link_128"><collision><geometry><cylinder length="0.6" radius="0.2" /></geometry><origin xyz="0 0 1" /></collision></link><link name="link_129"><collision><geometry><cylinder length="0.6" radius="0.2" /></geometry><origin xyz="0 0 1" /></collision></link><link name="link_130"><collision><geometry><cylinder length="0.6" radius="0.2" /></geometry><origin xyz="0 0 1" /></collision></link><link name="link_131"><collision><geometry><cylinder length="0.6" radius="0.2" /></geometry><origin xyz="0 0 1" /></collision></link><link name="link_132"><collision><geometry><cylinder length="0.6" radius="0.2" /></geometry><origin xyz="0 0 1" /></collision></link><link name="link_133"><collision><geometry><cylinder length="0.6" radius="0.2" /></geometry><origin xyz="0 0 1" /></collision></link><link name="link_134"><collision><geometry><cylinder length="0.6" radius="0.2" /></geometry><origin xyz="0 0 1" /></collision></link><link name="link_135"><collision><geometry><cylinder length="0.6" radius="0.2" /></geometry><origin xyz="0 0 1" /></collision></link><link name="link_136"><collision><geometry><cylinder length="0.6" radius="0.2" /></geometry><origin xyz="0 0 1" /></collision></link><link name="link_137"><collision><geometry><cylinder length="0.6" radius="0.2" /></geometry><origin xyz="0 0 1" /></collision></link><link name="link_138"><collision><geometry><cylinder length="0.6" radius="0.2" /></geometry><origin xyz="0 0 1" /></collision></link><link name="link_139"><collision><geometry><cylinder length="0.6" radius="0.2" /></geometry><origin xyz="0 0 1" /></collision></link><link name="link_140"><collision><geometry><cylinder length="0.6" radius="0.2" /></geometry><origin xyz="0 0 1" /></collision></link><link name="link_141"><collision><geometry><cylinder length="0.6" radius="0.2" /></geometry><origin xyz="0 0 1" /></collision></link><link name="link_142"><collision><geometry><cylinder length="0.6" radius="0.2" /></geometry><origin xyz="0 0 1" /></collision></link><link name="link_143"><collision><geometry><cylinder length="0.6" radius="0.2" /></geometry><origin xyz="0 0 1" /></collision></link><link name="link_144"><collision><geometry><cylinder length="0.6" radius="0.2" /></geometry><origin xyz="0 0 1" /></collision></link><link name="link_145"><collision><geometry><cylinder length="0.6" radius="0.2" /></geometry><origin xyz="0 0 1" /></collision></link><link name="link_146"><collision><geometry><cylinder length="0.6" radius="0.2" /></geometry><origin xyz="0 0 1" /></collision></link><link name="link_147"><collision><geometry><cylinder length="0.6" radius="0.2" /></geometry><origin xyz="0 0 1" /></collision></link><link name="link_148"><collision><geometry><cylinder length="0.6" radius="0.2" /></geometry><origin xyz="0 0 1" /></collision></link><link name="link_149"><collision><geometry><cylinder length="0.6" radius="0.2" /></geometry><origin xyz="0 0 1" /></collision></link><link name="link_150"><collision><geometry><cylinder length="0.6" radius="0.2" /></geometry><origin xyz="0 0 1" /></collision></link><link name="link_151"><collision><geometry><cylinder length="0.6" radius="0.2" /></geometry><origin xyz="0 0 1" /></collision></link><link name="link_152"><collision><geometry><cylinder length="0.6" radius="0.2" /></geometry><origin xyz="0 0 1" /></collision></link><link name="link_153"><collision><geometry><cylinder length="0.6" radius="0.2" /></geometry><origin xyz="0 0 1" /></collision></link><link name="link_154"><collision><geometry><cylinder length="0.6" radius="0.2" /></geometry><origin xyz="0 0 1" /></collision></link><link name="link_155"><collision><geometry><cylinder length="0.6" radius="0.2" /></geometry><origin xyz="0 0 1" /></collision></link><link name="link_156"><collision><geometry><cylinder length="0.6" radius="0.2" /></geometry><origin xyz="0 0 1" /></collision></link><link name="link_157"><collision><geometry><cylinder length="0.6" radius="0.2" /></geometry><origin xyz="0 0 1" /></collision></link><link name="link_158"><collision><geometry><cylinder length="0.6" radius="0.2" /></geometry><origin xyz="0 0 1" /></collision></link><link name="link_159"><collision><geometry><cylinder length="0.6" radius="0.2" /></geometry><origin xyz="0 0 1" /></collision></link><link name="link_160"><collision><geometry><cylinder length="0.6" radius="0.2" /></geometry><origin xyz="0 0 1" /></collision></link><link name="link_161"><collision><geometry><cylinder length="0.6" radius="0.2" /></geometry><origin xyz="0 0 1" /></collision></link><link name="link_162"><collision><geometry><cylinder length="0.6" radius="0.2" /></geometry><origin xyz="0 0 1" /></collision></link><link name="link_163"><collision><geometry><cylinder length="0.6" radius="0.2" /></geometry><origin xyz="0 0 1" /></collision></link><link name="link_164"><collision><geometry><cylinder length="0.6" radius="0.2" /></geometry><origin xyz="0 0 1" /></collision></link><link name="link_165"><collision><geometry><cylinder length="0.6" radius="0.2" /></geometry><origin xyz="0 0 1" /></collision></link><link name="link_166"><collision><geometry><cylinder length="0.6" radius="0.2" /></geometry><origin xyz="0 0 1" /></collision></link><link name="link_167"><collision><geometry><cylinder length="0.6" radius="0.2" /></geometry><origin xyz="0 0 1" /></collision></link><link name="link_168"><collision><geometry><cylinder length="0.6" radius="0.2" /></geometry><origin xyz="0 0 1" /></collision></link><link name="link_169"><collision><geometry><cylinder length="0.6" radius="0.2" /></geometry><origin xyz="0 0 1" /></collision></link><link name="link_170"><collision><geometry><cylinder length="0.6" radius="0.2" /></geometry><origin xyz="0 0 1" /></collision></link><link name="link_171"><collision><geometry><cylinder length="0.6" radius="0.2" /></geometry><origin xyz="0 0 1" /></collision></link><link name="link_172"><collision><geometry><cylinder length="0.6" radius="0.2" /></geometry><origin xyz="0 0 1" /></collision></link><link name="link_173"><collision><geometry><cylinder length="0.6" radius="0.2" /></geometry><origin xyz="0 0 1" /></collision></link><link name="link_174"><collision><geometry><cylinder length="0.6" radius="0.2" /></geometry><origin xyz="0 0 1" /></collision></link><link name="link_175"><collision><geometry><cylinder length="0.6" radius="0.2" /></geometry><origin xyz="0 0 1" /></collision></link><link name="link_176"><collision><geometry><cylinder length="0.6" radius="0.2" /></geometry><origin xyz="0 0 1" /></collision></link><link name="link_177"><collision><geometry><cylinder length="0.6" radius="0.2" /></geometry><origin xyz="0 0 1" /></collision></link><link name="link_178"><collision><geometry><cylinder length="0.6" radius="0.2" /></geometry><origin xyz="0 0 1" /></collision></link><link name="link_179"><collision><geometry><cylinder length="0.6" radius="0.2" /></geometry><origin xyz="0 0 1" /></collision></link><link name="link_180"><collision><geometry><cylinder length="0.6" radius="0.2" /></geometry><origin xyz="0 0 1" /></collision></link><link name="link_181"><collision><geometry><cylinder length="0.6" radius="0.2" /></geometry><origin xyz="0 0 1" /></collision></link><link name="link_182"><collision><geometry><cylinder length="0.6" radius="0.2" /></geometry><origin xyz="0 0 1" /></collision></link><link name="link_183"><collision><geometry><cylinder length="0.6" radius="0.2" /></geometry><origin xyz="0 0 1" /></collision></link><link name="link_184"><collision><geometry><cylinder length="0.6" radius="0.2" /></geometry><origin xyz="0 0 1" /></collision></link><link name="link_185"><collision><geometry><cylinder length="0.6" radius="0.2" /></geometry><origin xyz="0 0 1" /></collision></link><link name="link_186"><collision><geometry><cylinder length="0.6" radius="0.2" /></geometry><origin xyz="0 0 1" /></collision></link><link name="link_187"><collision><geometry><cylinder length="0.6" radius="0.2" /></geometry><origin xyz="0 0 1" /></collision></link><link name="link_188"><collision><geometry><cylinder length="0.6" radius="0.2" /></geometry><origin xyz="0 0 1" /></collision></link><link name="link_189"><collision><geometry><cylinder length="0.6" radius="0.2" /></geometry><origin xyz="0 0 1" /></collision></link><link name="link_190"><collision><geometry><cylinder length="0.6" radius="0.2" /></geometry><origin xyz="0 0 1" /></collision></link><link name="link_191"><collision><geometry><cylinder length="0.6" radius="0.2" /></geometry><origin xyz="0 0 1" /></collision></link><link name="link_192"><collision><geometry><cylinder length="0.6" radius="0.2" /></geometry><origin xyz="0 0 1" /></collision></link><link name="link_193"><collision><geometry><cylinder length="0.6" radius="0.2" /></geometry><origin xyz="0 0 1" /></collision></link><link name="link_194"><collision><geometry><cylinder length="0.6" radius="0.2" /></geometry><origin xyz="0 0 1" /></collision></link><link name="link_195"><collision><geometry><cylinder length="0.6" radius="0.2" /></geometry><origin xyz="0 0 1" /></collision></link><link name="link_196"><collision><geometry><cylinder length="0.6" radius="0.2" /></geometry><origin xyz="0 0 1" /></collision></link><link name="link_197"><collision><geometry><cylinder length="0.6" radius="0.2" /></geometry><origin xyz="0 0 1" /></collision></link><link name="link_198"><collision><geometry><cylinder length="0.6" radius="0.2" /></geometry><origin xyz="0 0 1" /></collision></link><link name="link_199"><collision><geometry><cylinder length="0.6" radius="0.2" /></geometry><origin xyz="0 0 1" /></collision></link><link name="link_200"><collision><geometry><cylinder length="0.6" radius="0.2" /></geometry><origin xyz="0 0 1" /></collision></link><link name="link_201"><collision><geometry><cylinder length="0.6" radius="0.2" /></geometry><origin xyz="0 0 1" /></collision></link><link name="link_202"><collision><geometry><cylinder length="0.6" radius="0.2" /></geometry><origin xyz="0 0 1" /></collision></link><link name="link_203"><collision><geometry><cylinder length="0.6" radius="0.2" /></geometry><origin xyz="0 0 1" /></collision></link><link name="link_204"><collision><geometry><cylinder length="0.6" radius="0.2" /></geometry><origin xyz="0 0 1" /></collision></link><link name="link_205"><collision><geometry><cylinder length="0.6" radius="0.2" /></geometry><origin xyz="0 0 1" /></collision></link><link name="link_206"><collision><geometry><cylinder length="0.6" radius="0.2" /></geometry><origin xyz="0 0 1" /></collision></link><link name="link_207"><collision><geometry><cylinder length="0.6" radius="0.2" /></geometry><origin xyz="0 0 1" /></collision></link><link name="link_208"><collision><geometry><cylinder length="0.6" radius="0.2" /></geometry><origin xyz="0 0 1" /></collision></link><link name="link_209"><collision><geometry><cylinder length="0.6" radius="0.2" /></geometry><origin xyz="0 0 1" /></collision></link><link name="link_210"><collision><geometry><cylinder length="0.6" radius="0.2" /></geometry><origin xyz="0 0 1" /></collision></link><link name="link_211"><collision><geometry><cylinder length="0.6" radius="0.2" /></geometry><origin xyz="0 0 1" /></collision></link><link name="link_212"><collision><geometry><cylinder length="0.6" radius="0.2" /></geometry><origin xyz="0 0 1" /></collision></link><link name="link_213"><collision><geometry><cylinder length="0.6" radius="0.2" /></geometry><origin xyz="0 0 1" /></collision></link><link name="link_214"><collision><geometry><cylinder length="0.6" radius="0.2" /></geometry><origin xyz="0 0 1" /></collision></link><link name="link_215"><collision><geometry><cylinder length="0.6" radius="0.2" /></geometry><origin xyz="0 0 1" /></collision></link><link name="link_216"><collision><geometry><cylinder length="0.6" radius="0.2" /></geometry><origin xyz="0 0 1" /></collision></link><link name="link_217"><collision><geometry><cylinder length="0.6" radius="0.2" /></geometry><origin xyz="0 0 1" /></collision></link><link name="link_218"><collision><geometry><cylinder length="0.6" radius="0.2" /></geometry><origin xyz="0 0 1" /></collision></link><link name="link_219"><collision><geometry><cylinder length="0.6" radius="0.2" /></geometry><origin xyz="0 0 1" /></collision></link><link name="link_220"><collision><geometry><cylinder length="0.6" radius="0.2" /></geometry><origin xyz="0 0 1" /></collision></link><link name="link_221"><collision><geometry><cylinder length="0.6" radius="0.2" /></geometry><origin xyz="0 0 1" /></collision></link><link name="link_222"><collision><geometry><cylinder length="0.6" radius="0.2" /></geometry><origin xyz="0 0 1" /></collision></link><link name="link_223"><collision><geometry><cylinder length="0.6" radius="0.2" /></geometry><origin xyz="0 0 1" /></collision></link><link name="link_224"><collision><geometry><cylinder length="0.6" radius="0.2" /></geometry><origin xyz="0 0 1" /></collision></link><link name="link_225"><collision><geometry><cylinder length="0.6" radius="0.2" /></geometry><origin xyz="0 0 1" /></collision></link><link name="link_226"><collision><geometry><cylinder length="0.6" radius="0.2" /></geometry><origin xyz="0 0 1" /></collision></link><link name="link_227"><collision><geometry><cylinder length="0.6" radius="0.2" /></geometry><origin xyz="0 0 1" /></collision></link><link name="link_228"><collision><geometry><cylinder length="0.6" radius="0.2" /></geometry><origin xyz="0 0 1" /></collision></link><link name="link_229"><collision><geometry><cylinder length="0.6" radius="0.2" /></geometry><origin xyz="0 0 1" /></collision></link><link name="link_230"><collision><geometry><cylinder length="0.6" radius="0.2" /></geometry><origin xyz="0 0 1" /></collision></link><link name="link_231"><collision><geometry><cylinder length="0.6" radius="0.2" /></geometry><origin xyz="0 0 1" /></collision></link><link name="link_232"><collision><geometry><cylinder length="0.6" radius="0.2" /></geometry><origin xyz="0 0 1" /></collision></link><link name="link_233"><collision><geometry><cylinder length="0.6" radius="0.2" /></geometry><origin xyz="0 0 1" /></collision></link><link name="link_234"><collision><geometry><cylinder length="0.6" radius="0.2" /></geometry><origin xyz="0 0 1" /></collision></link><joint name="link_0_to_link_1" type="continuous"><parent link="link_0" /><child link="link_1" /><origin xyz="0 0 2" /><xyz xyz="1 0 0" /></joint><joint name="link_1_to_link_2" type="continuous"><parent link="link_1" /><child link="link_2" /><origin xyz="0 0 2" /><xyz xyz="1 0 0" /></joint><joint name="link_2_to_link_3" type="continuous"><parent link="link_2" /><child link="link_3" /><origin xyz="0 0 2" /><xyz xyz="1 0 0" /></joint><joint name="link_3_to_link_4" type="continuous"><parent link="link_3" /><child link="link_4" /><origin xyz="0 0 2" /><xyz xyz="1 0 0" /></joint><joint name="link_4_to_link_5" type="continuous"><parent link="link_4" /><child link="link_5" /><origin xyz="0 0 2" /><xyz xyz="1 0 0" /></joint><joint name="link_5_to_link_6" type="continuous"><parent link="link_5" /><child link="link_6" /><origin xyz="0 0 2" /><xyz xyz="1 0 0" /></joint><joint name="link_6_to_link_7" type="continuous"><parent link="link_6" /><child link="link_7" /><origin xyz="0 0 2" /><xyz xyz="1 0 0" /></joint><joint name="link_7_to_link_8" type="continuous"><parent link="link_7" /><child link="link_8" /><origin xyz="0 0 2" /><xyz xyz="1 0 0" /></joint><joint name="link_8_to_link_9" type="continuous"><parent link="link_8" /><child link="link_9" /><origin xyz="0 0 2" /><xyz xyz="1 0 0" /></joint><joint name="link_9_to_link_10" type="continuous"><parent link="link_9" /><child link="link_10" /><origin xyz="0 0 2" /><xyz xyz="1 0 0" /></joint><joint name="link_10_to_link_11" type="continuous"><parent link="link_10" /><child link="link_11" /><origin xyz="0 0 2" /><xyz xyz="1 0 0" /></joint><joint name="link_11_to_link_12" type="continuous"><parent link="link_11" /><child link="link_12" /><origin xyz="0 0 2" /><xyz xyz="1 0 0" /></joint><joint name="link_12_to_link_13" type="continuous"><parent link="link_12" /><child link="link_13" /><origin xyz="0 0 2" /><xyz xyz="1 0 0" /></joint><joint name="link_13_to_link_14" type="continuous"><parent link="link_13" /><child link="link_14" /><origin xyz="0 0 2" /><xyz xyz="1 0 0" /></joint><joint name="link_14_to_link_15" type="continuous"><parent link="link_14" /><child link="link_15" /><origin xyz="0 0 2" /><xyz xyz="1 0 0" /></joint><joint name="link_15_to_link_16" type="continuous"><parent link="link_15" /><child link="link_16" /><origin xyz="0 0 2" /><xyz xyz="1 0 0" /></joint><joint name="link_16_to_link_17" type="continuous"><parent link="link_16" /><child link="link_17" /><origin xyz="0 0 2" /><xyz xyz="1 0 0" /></joint><joint name="link_17_to_link_18" type="continuous"><parent link="link_17" /><child link="link_18" /><origin xyz="0 0 2" /><xyz xyz="1 0 0" /></joint><joint name="link_18_to_link_19" type="continuous"><parent link="link_18" /><child link="link_19" /><origin xyz="0 0 2" /><xyz xyz="1 0 0" /></joint><joint name="link_19_to_link_20" type="continuous"><parent link="link_19" /><child link="link_20" /><origin xyz="0 0 2" /><xyz xyz="1 0 0" /></joint><joint name="link_20_to_link_21" type="continuous"><parent link="link_20" /><child link="link_21" /><origin xyz="0 0 2" /><xyz xyz="1 0 0" /></joint><joint name="link_21_to_link_22" type="continuous"><parent link="link_21" /><child link="link_22" /><origin xyz="0 0 2" /><xyz xyz="1 0 0" /></joint><joint name="link_22_to_link_23" type="continuous"><parent link="link_22" /><child link="link_23" /><origin xyz="0 0 2" /><xyz xyz="1 0 0" /></joint><joint name="link_23_to_link_24" type="continuous"><parent link="link_23" /><child link="link_24" /><origin xyz="0 0 2" /><xyz xyz="1 0 0" /></joint><joint name="link_24_to_link_25" type="continuous"><parent link="link_24" /><child link="link_25" /><origin xyz="0 0 2" /><xyz xyz="1 0 0" /></joint><joint name="link_25_to_link_26" type="continuous"><parent link="link_25" /><child link="link_26" /><origin xyz="0 0 2" /><xyz xyz="1 0 0" /></joint><joint name="link_26_to_link_27" type="continuous"><parent link="link_26" /><child link="link_27" /><origin xyz="0 0 2" /><xyz xyz="1 0 0" /></joint><joint name="link_27_to_link_28" type="continuous"><parent link="link_27" /><child link="link_28" /><origin xyz="0 0 2" /><xyz xyz="1 0 0" /></joint><joint name="link_28_to_link_29" type="continuous"><parent link="link_28" /><child link="link_29" /><origin xyz="0 0 2" /><xyz xyz="1 0 0" /></joint><joint name="link_29_to_link_30" type="continuous"><parent link="link_29" /><child link="link_30" /><origin xyz="0 0 2" /><xyz xyz="1 0 0" /></joint><joint name="link_30_to_link_31" type="continuous"><parent link="link_30" /><child link="link_31" /><origin xyz="0 0 2" /><xyz xyz="1 0 0" /></joint><joint name="link_31_to_link_32" type="continuous"><parent link="link_31" /><child link="link_32" /><origin xyz="0 0 2" /><xyz xyz="1 0 0" /></joint><joint name="link_32_to_link_33" type="continuous"><parent link="link_32" /><child link="link_33" /><origin xyz="0 0 2" /><xyz xyz="1 0 0" /></joint><joint name="link_33_to_link_34" type="continuous"><parent link="link_33" /><child link="link_34" /><origin xyz="0 0 2" /><xyz xyz="1 0 0" /></joint><joint name="link_34_to_link_35" type="continuous"><parent link="link_34" /><child link="link_35" /><origin xyz="0 0 2" /><xyz xyz="1 0 0" /></joint><joint name="link_35_to_link_36" type="continuous"><parent link="link_35" /><child link="link_36" /><origin xyz="0 0 2" /><xyz xyz="1 0 0" /></joint><joint name="link_36_to_link_37" type="continuous"><parent link="link_36" /><child link="link_37" /><origin xyz="0 0 2" /><xyz xyz="1 0 0" /></joint><joint name="link_37_to_link_38" type="continuous"><parent link="link_37" /><child link="link_38" /><origin xyz="0 0 2" /><xyz xyz="1 0 0" /></joint><joint name="link_38_to_link_39" type="continuous"><parent link="link_38" /><child link="link_39" /><origin xyz="0 0 2" /><xyz xyz="1 0 0" /></joint><joint name="link_39_to_link_40" type="continuous"><parent link="link_39" /><child link="link_40" /><origin xyz="0 0 2" /><xyz xyz="1 0 0" /></joint><joint name="link_40_to_link_41" type="continuous"><parent link="link_40" /><child link="link_41" /><origin xyz="0 0 2" /><xyz xyz="1 0 0" /></joint><joint name="link_41_to_link_42" type="continuous"><parent link="link_41" /><child link="link_42" /><origin xyz="0 0 2" /><xyz xyz="1 0 0" /></joint><joint name="link_42_to_link_43" type="continuous"><parent link="link_42" /><child link="link_43" /><origin xyz="0 0 2" /><xyz xyz="1 0 0" /></joint><joint name="link_43_to_link_44" type="continuous"><parent link="link_43" /><child link="link_44" /><origin xyz="0 0 2" /><xyz xyz="1 0 0" /></joint><joint name="link_44_to_link_45" type="continuous"><parent link="link_44" /><child link="link_45" /><origin xyz="0 0 2" /><xyz xyz="1 0 0" /></joint><joint name="link_45_to_link_46" type="continuous"><parent link="link_45" /><child link="link_46" /><origin xyz="0 0 2" /><xyz xyz="1 0 0" /></joint><joint name="link_46_to_link_47" type="continuous"><parent link="link_46" /><child link="link_47" /><origin xyz="0 0 2" /><xyz xyz="1 0 0" /></joint><joint name="link_47_to_link_48" type="continuous"><parent link="link_47" /><child link="link_48" /><origin xyz="0 0 2" /><xyz xyz="1 0 0" /></joint><joint name="link_48_to_link_49" type="continuous"><parent link="link_48" /><child link="link_49" /><origin xyz="0 0 2" /><xyz xyz="1 0 0" /></joint><joint name="link_49_to_link_50" type="continuous"><parent link="link_49" /><child link="link_50" /><origin xyz="0 0 2" /><xyz xyz="1 0 0" /></joint><joint name="link_50_to_link_51" type="continuous"><parent link="link_50" /><child link="link_51" /><origin xyz="0 0 2" /><xyz xyz="1 0 0" /></joint><joint name="link_51_to_link_52" type="continuous"><parent link="link_51" /><child link="link_52" /><origin xyz="0 0 2" /><xyz xyz="1 0 0" /></joint><joint name="link_52_to_link_53" type="continuous"><parent link="link_52" /><child link="link_53" /><origin xyz="0 0 2" /><xyz xyz="1 0 0" /></joint><joint name="link_53_to_link_54" type="continuous"><parent link="link_53" /><child link="link_54" /><origin xyz="0 0 2" /><xyz xyz="1 0 0" /></joint><joint name="link_54_to_link_55" type="continuous"><parent link="link_54" /><child link="link_55" /><origin xyz="0 0 2" /><xyz xyz="1 0 0" /></joint><joint name="link_55_to_link_56" type="continuous"><parent link="link_55" /><child link="link_56" /><origin xyz="0 0 2" /><xyz xyz="1 0 0" /></joint><joint name="link_56_to_link_57" type="continuous"><parent link="link_56" /><child link="link_57" /><origin xyz="0 0 2" /><xyz xyz="1 0 0" /></joint><joint name="link_57_to_link_58" type="continuous"><parent link="link_57" /><child link="link_58" /><origin xyz="0 0 2" /><xyz xyz="1 0 0" /></joint><joint name="link_58_to_link_59" type="continuous"><parent link="link_58" /><child link="link_59" /><origin xyz="0 0 2" /><xyz xyz="1 0 0" /></joint><joint name="link_59_to_link_60" type="continuous"><parent link="link_59" /><child link="link_60" /><origin xyz="0 0 2" /><xyz xyz="1 0 0" /></joint><joint name="link_60_to_link_61" type="continuous"><parent link="link_60" /><child link="link_61" /><origin xyz="0 0 2" /><xyz xyz="1 0 0" /></joint><joint name="link_61_to_link_62" type="continuous"><parent link="link_61" /><child link="link_62" /><origin xyz="0 0 2" /><xyz xyz="1 0 0" /></joint><joint name="link_62_to_link_63" type="continuous"><parent link="link_62" /><child link="link_63" /><origin xyz="0 0 2" /><xyz xyz="1 0 0" /></joint><joint name="link_63_to_link_64" type="continuous"><parent link="link_63" /><child link="link_64" /><origin xyz="0 0 2" /><xyz xyz="1 0 0" /></joint><joint name="link_64_to_link_65" type="continuous"><parent link="link_64" /><child link="link_65" /><origin xyz="0 0 2" /><xyz xyz="1 0 0" /></joint><joint name="link_65_to_link_66" type="continuous"><parent link="link_65" /><child link="link_66" /><origin xyz="0 0 2" /><xyz xyz="1 0 0" /></joint><joint name="link_66_to_link_67" type="continuous"><parent link="link_66" /><child link="link_67" /><origin xyz="0 0 2" /><xyz xyz="1 0 0" /></joint><joint name="link_67_to_link_68" type="continuous"><parent link="link_67" /><child link="link_68" /><origin xyz="0 0 2" /><xyz xyz="1 0 0" /></joint><joint name="link_68_to_link_69" type="continuous"><parent link="link_68" /><child link="link_69" /><origin xyz="0 0 2" /><xyz xyz="1 0 0" /></joint><joint name="link_69_to_link_70" type="continuous"><parent link="link_69" /><child link="link_70" /><origin xyz="0 0 2" /><xyz xyz="1 0 0" /></joint><joint name="link_70_to_link_71" type="continuous"><parent link="link_70" /><child link="link_71" /><origin xyz="0 0 2" /><xyz xyz="1 0 0" /></joint><joint name="link_71_to_link_72" type="continuous"><parent link="link_71" /><child link="link_72" /><origin xyz="0 0 2" /><xyz xyz="1 0 0" /></joint><joint name="link_72_to_link_73" type="continuous"><parent link="link_72" /><child link="link_73" /><origin xyz="0 0 2" /><xyz xyz="1 0 0" /></joint><joint name="link_73_to_link_74" type="continuous"><parent link="link_73" /><child link="link_74" /><origin xyz="0 0 2" /><xyz xyz="1 0 0" /></joint><joint name="link_74_to_link_75" type="continuous"><parent link="link_74" /><child link="link_75" /><origin xyz="0 0 2" /><xyz xyz="1 0 0" /></joint><joint name="link_75_to_link_76" type="continuous"><parent link="link_75" /><child link="link_76" /><origin xyz="0 0 2" /><xyz xyz="1 0 0" /></joint><joint name="link_76_to_link_77" type="continuous"><parent link="link_76" /><child link="link_77" /><origin xyz="0 0 2" /><xyz xyz="1 0 0" /></joint><joint name="link_77_to_link_78" type="continuous"><parent link="link_77" /><child link="link_78" /><origin xyz="0 0 2" /><xyz xyz="1 0 0" /></joint><joint name="link_78_to_link_79" type="continuous"><parent link="link_78" /><child link="link_79" /><origin xyz="0 0 2" /><xyz xyz="1 0 0" /></joint><joint name="link_79_to_link_80" type="continuous"><parent link="link_79" /><child link="link_80" /><origin xyz="0 0 2" /><xyz xyz="1 0 0" /></joint><joint name="link_80_to_link_81" type="continuous"><parent link="link_80" /><child link="link_81" /><origin xyz="0 0 2" /><xyz xyz="1 0 0" /></joint><joint name="link_81_to_link_82" type="continuous"><parent link="link_81" /><child link="link_82" /><origin xyz="0 0 2" /><xyz xyz="1 0 0" /></joint><joint name="link_82_to_link_83" type="continuous"><parent link="link_82" /><child link="link_83" /><origin xyz="0 0 2" /><xyz xyz="1 0 0" /></joint><joint name="link_83_to_link_84" type="continuous"><parent link="link_83" /><child link="link_84" /><origin xyz="0 0 2" /><xyz xyz="1 0 0" /></joint><joint name="link_84_to_link_85" type="continuous"><parent link="link_84" /><child link="link_85" /><origin xyz="0 0 2" /><xyz xyz="1 0 0" /></joint><joint name="link_85_to_link_86" type="continuous"><parent link="link_85" /><child link="link_86" /><origin xyz="0 0 2" /><xyz xyz="1 0 0" /></joint><joint name="link_86_to_link_87" type="continuous"><parent link="link_86" /><child link="link_87" /><origin xyz="0 0 2" /><xyz xyz="1 0 0" /></joint><joint name="link_87_to_link_88" type="continuous"><parent link="link_87" /><child link="link_88" /><origin xyz="0 0 2" /><xyz xyz="1 0 0" /></joint><joint name="link_88_to_link_89" type="continuous"><parent link="link_88" /><child link="link_89" /><origin xyz="0 0 2" /><xyz xyz="1 0 0" /></joint><joint name="link_89_to_link_90" type="continuous"><parent link="link_89" /><child link="link_90" /><origin xyz="0 0 2" /><xyz xyz="1 0 0" /></joint><joint name="link_90_to_link_91" type="continuous"><parent link="link_90" /><child link="link_91" /><origin xyz="0 0 2" /><xyz xyz="1 0 0" /></joint><joint name="link_91_to_link_92" type="continuous"><parent link="link_91" /><child link="link_92" /><origin xyz="0 0 2" /><xyz xyz="1 0 0" /></joint><joint name="link_92_to_link_93" type="continuous"><parent link="link_92" /><child link="link_93" /><origin xyz="0 0 2" /><xyz xyz="1 0 0" /></joint><joint name="link_93_to_link_94" type="continuous"><parent link="link_93" /><child link="link_94" /><origin xyz="0 0 2" /><xyz xyz="1 0 0" /></joint><joint name="link_94_to_link_95" type="continuous"><parent link="link_94" /><child link="link_95" /><origin xyz="0 0 2" /><xyz xyz="1 0 0" /></joint><joint name="link_95_to_link_96" type="continuous"><parent link="link_95" /><child link="link_96" /><origin xyz="0 0 2" /><xyz xyz="1 0 0" /></joint><joint name="link_96_to_link_97" type="continuous"><parent link="link_96" /><child link="link_97" /><origin xyz="0 0 2" /><xyz xyz="1 0 0" /></joint><joint name="link_97_to_link_98" type="continuous"><parent link="link_97" /><child link="link_98" /><origin xyz="0 0 2" /><xyz xyz="1 0 0" /></joint><joint name="link_98_to_link_99" type="continuous"><parent link="link_98" /><child link="link_99" /><origin xyz="0 0 2" /><xyz xyz="1 0 0" /></joint><joint name="link_99_to_link_100" type="continuous"><parent link="link_99" /><child link="link_100" /><origin xyz="0 0 2" /><xyz xyz="1 0 0" /></joint><joint name="link_100_to_link_101" type="continuous"><parent link="link_100" /><child link="link_101" /><origin xyz="0 0 2" /><xyz xyz="1 0 0" /></joint><joint name="link_101_to_link_102" type="continuous"><parent link="link_101" /><child link="link_102" /><origin xyz="0 0 2" /><xyz xyz="1 0 0" /></joint><joint name="link_102_to_link_103" type="continuous"><parent link="link_102" /><child link="link_103" /><origin xyz="0 0 2" /><xyz xyz="1 0 0" /></joint><joint name="link_103_to_link_104" type="continuous"><parent link="link_103" /><child link="link_104" /><origin xyz="0 0 2" /><xyz xyz="1 0 0" /></joint><joint name="link_104_to_link_105" type="continuous"><parent link="link_104" /><child link="link_105" /><origin xyz="0 0 2" /><xyz xyz="1 0 0" /></joint><joint name="link_105_to_link_106" type="continuous"><parent link="link_105" /><child link="link_106" /><origin xyz="0 0 2" /><xyz xyz="1 0 0" /></joint><joint name="link_106_to_link_107" type="continuous"><parent link="link_106" /><child link="link_107" /><origin xyz="0 0 2" /><xyz xyz="1 0 0" /></joint><joint name="link_107_to_link_108" type="continuous"><parent link="link_107" /><child link="link_108" /><origin xyz="0 0 2" /><xyz xyz="1 0 0" /></joint><joint name="link_108_to_link_109" type="continuous"><parent link="link_108" /><child link="link_109" /><origin xyz="0 0 2" /><xyz xyz="1 0 0" /></joint><joint name="link_109_to_link_110" type="continuous"><parent link="link_109" /><child link="link_110" /><origin xyz="0 0 2" /><xyz xyz="1 0 0" /></joint><joint name="link_110_to_link_111" type="continuous"><parent link="link_110" /><child link="link_111" /><origin xyz="0 0 2" /><xyz xyz="1 0 0" /></joint><joint name="link_111_to_link_112" type="continuous"><parent link="link_111" /><child link="link_112" /><origin xyz="0 0 2" /><xyz xyz="1 0 0" /></joint><joint name="link_112_to_link_113" type="continuous"><parent link="link_112" /><child link="link_113" /><origin xyz="0 0 2" /><xyz xyz="1 0 0" /></joint><joint name="link_113_to_link_114" type="continuous"><parent link="link_113" /><child link="link_114" /><origin xyz="0 0 2" /><xyz xyz="1 0 0" /></joint><joint name="link_114_to_link_115" type="continuous"><parent link="link_114" /><child link="link_115" /><origin xyz="0 0 2" /><xyz xyz="1 0 0" /></joint><joint name="link_115_to_link_116" type="continuous"><parent link="link_115" /><child link="link_116" /><origin xyz="0 0 2" /><xyz xyz="1 0 0" /></joint><joint name="link_116_to_link_117" type="continuous"><parent link="link_116" /><child link="link_117" /><origin xyz="0 0 2" /><xyz xyz="1 0 0" /></joint><joint name="link_117_to_link_118" type="continuous"><parent link="link_117" /><child link="link_118" /><origin xyz="0 0 2" /><xyz xyz="1 0 0" /></joint><joint name="link_118_to_link_119" type="continuous"><parent link="link_118" /><child link="link_119" /><origin xyz="0 0 2" /><xyz xyz="1 0 0" /></joint><joint name="link_119_to_link_120" type="continuous"><parent link="link_119" /><child link="link_120" /><origin xyz="0 0 2" /><xyz xyz="1 0 0" /></joint><joint name="link_120_to_link_121" type="continuous"><parent link="link_120" /><child link="link_121" /><origin xyz="0 0 2" /><xyz xyz="1 0 0" /></joint><joint name="link_121_to_link_122" type="continuous"><parent link="link_121" /><child link="link_122" /><origin xyz="0 0 2" /><xyz xyz="1 0 0" /></joint><joint name="link_122_to_link_123" type="continuous"><parent link="link_122" /><child link="link_123" /><origin xyz="0 0 2" /><xyz xyz="1 0 0" /></joint><joint name="link_123_to_link_124" type="continuous"><parent link="link_123" /><child link="link_124" /><origin xyz="0 0 2" /><xyz xyz="1 0 0" /></joint><joint name="link_124_to_link_125" type="continuous"><parent link="link_124" /><child link="link_125" /><origin xyz="0 0 2" /><xyz xyz="1 0 0" /></joint><joint name="link_125_to_link_126" type="continuous"><parent link="link_125" /><child link="link_126" /><origin xyz="0 0 2" /><xyz xyz="1 0 0" /></joint><joint name="link_126_to_link_127" type="continuous"><parent link="link_126" /><child link="link_127" /><origin xyz="0 0 2" /><xyz xyz="1 0 0" /></joint><joint name="link_127_to_link_128" type="continuous"><parent link="link_127" /><child link="link_128" /><origin xyz="0 0 2" /><xyz xyz="1 0 0" /></joint><joint name="link_128_to_link_129" type="continuous"><parent link="link_128" /><child link="link_129" /><origin xyz="0 0 2" /><xyz xyz="1 0 0" /></joint><joint name="link_129_to_link_130" type="continuous"><parent link="link_129" /><child link="link_130" /><origin xyz="0 0 2" /><xyz xyz="1 0 0" /></joint><joint name="link_130_to_link_131" type="continuous"><parent link="link_130" /><child link="link_131" /><origin xyz="0 0 2" /><xyz xyz="1 0 0" /></joint><joint name="link_131_to_link_132" type="continuous"><parent link="link_131" /><child link="link_132" /><origin xyz="0 0 2" /><xyz xyz="1 0 0" /></joint><joint name="link_132_to_link_133" type="continuous"><parent link="link_132" /><child link="link_133" /><origin xyz="0 0 2" /><xyz xyz="1 0 0" /></joint><joint name="link_133_to_link_134" type="continuous"><parent link="link_133" /><child link="link_134" /><origin xyz="0 0 2" /><xyz xyz="1 0 0" /></joint><joint name="link_134_to_link_135" type="continuous"><parent link="link_134" /><child link="link_135" /><origin xyz="0 0 2" /><xyz xyz="1 0 0" /></joint><joint name="link_135_to_link_136" type="continuous"><parent link="link_135" /><child link="link_136" /><origin xyz="0 0 2" /><xyz xyz="1 0 0" /></joint><joint name="link_136_to_link_137" type="continuous"><parent link="link_136" /><child link="link_137" /><origin xyz="0 0 2" /><xyz xyz="1 0 0" /></joint><joint name="link_137_to_link_138" type="continuous"><parent link="link_137" /><child link="link_138" /><origin xyz="0 0 2" /><xyz xyz="1 0 0" /></joint><joint name="link_138_to_link_139" type="continuous"><parent link="link_138" /><child link="link_139" /><origin xyz="0 0 2" /><xyz xyz="1 0 0" /></joint><joint name="link_139_to_link_140" type="continuous"><parent link="link_139" /><child link="link_140" /><origin xyz="0 0 2" /><xyz xyz="1 0 0" /></joint><joint name="link_140_to_link_141" type="continuous"><parent link="link_140" /><child link="link_141" /><origin xyz="0 0 2" /><xyz xyz="1 0 0" /></joint><joint name="link_141_to_link_142" type="continuous"><parent link="link_141" /><child link="link_142" /><origin xyz="0 0 2" /><xyz xyz="1 0 0" /></joint><joint name="link_142_to_link_143" type="continuous"><parent link="link_142" /><child link="link_143" /><origin xyz="0 0 2" /><xyz xyz="1 0 0" /></joint><joint name="link_143_to_link_144" type="continuous"><parent link="link_143" /><child link="link_144" /><origin xyz="0 0 2" /><xyz xyz="1 0 0" /></joint><joint name="link_144_to_link_145" type="continuous"><parent link="link_144" /><child link="link_145" /><origin xyz="0 0 2" /><xyz xyz="1 0 0" /></joint><joint name="link_145_to_link_146" type="continuous"><parent link="link_145" /><child link="link_146" /><origin xyz="0 0 2" /><xyz xyz="1 0 0" /></joint><joint name="link_146_to_link_147" type="continuous"><parent link="link_146" /><child link="link_147" /><origin xyz="0 0 2" /><xyz xyz="1 0 0" /></joint><joint name="link_147_to_link_148" type="continuous"><parent link="link_147" /><child link="link_148" /><origin xyz="0 0 2" /><xyz xyz="1 0 0" /></joint><joint name="link_148_to_link_149" type="continuous"><parent link="link_148" /><child link="link_149" /><origin xyz="0 0 2" /><xyz xyz="1 0 0" /></joint><joint name="link_149_to_link_150" type="continuous"><parent link="link_149" /><child link="link_150" /><origin xyz="0 0 2" /><xyz xyz="1 0 0" /></joint><joint name="link_150_to_link_151" type="continuous"><parent link="link_150" /><child link="link_151" /><origin xyz="0 0 2" /><xyz xyz="1 0 0" /></joint><joint name="link_151_to_link_152" type="continuous"><parent link="link_151" /><child link="link_152" /><origin xyz="0 0 2" /><xyz xyz="1 0 0" /></joint><joint name="link_152_to_link_153" type="continuous"><parent link="link_152" /><child link="link_153" /><origin xyz="0 0 2" /><xyz xyz="1 0 0" /></joint><joint name="link_153_to_link_154" type="continuous"><parent link="link_153" /><child link="link_154" /><origin xyz="0 0 2" /><xyz xyz="1 0 0" /></joint><joint name="link_154_to_link_155" type="continuous"><parent link="link_154" /><child link="link_155" /><origin xyz="0 0 2" /><xyz xyz="1 0 0" /></joint><joint name="link_155_to_link_156" type="continuous"><parent link="link_155" /><child link="link_156" /><origin xyz="0 0 2" /><xyz xyz="1 0 0" /></joint><joint name="link_156_to_link_157" type="continuous"><parent link="link_156" /><child link="link_157" /><origin xyz="0 0 2" /><xyz xyz="1 0 0" /></joint><joint name="link_157_to_link_158" type="continuous"><parent link="link_157" /><child link="link_158" /><origin xyz="0 0 2" /><xyz xyz="1 0 0" /></joint><joint name="link_158_to_link_159" type="continuous"><parent link="link_158" /><child link="link_159" /><origin xyz="0 0 2" /><xyz xyz="1 0 0" /></joint><joint name="link_159_to_link_160" type="continuous"><parent link="link_159" /><child link="link_160" /><origin xyz="0 0 2" /><xyz xyz="1 0 0" /></joint><joint name="link_160_to_link_161" type="continuous"><parent link="link_160" /><child link="link_161" /><origin xyz="0 0 2" /><xyz xyz="1 0 0" /></joint><joint name="link_161_to_link_162" type="continuous"><parent link="link_161" /><child link="link_162" /><origin xyz="0 0 2" /><xyz xyz="1 0 0" /></joint><joint name="link_162_to_link_163" type="continuous"><parent link="link_162" /><child link="link_163" /><origin xyz="0 0 2" /><xyz xyz="1 0 0" /></joint><joint name="link_163_to_link_164" type="continuous"><parent link="link_163" /><child link="link_164" /><origin xyz="0 0 2" /><xyz xyz="1 0 0" /></joint><joint name="link_164_to_link_165" type="continuous"><parent link="link_164" /><child link="link_165" /><origin xyz="0 0 2" /><xyz xyz="1 0 0" /></joint><joint name="link_165_to_link_166" type="continuous"><parent link="link_165" /><child link="link_166" /><origin xyz="0 0 2" /><xyz xyz="1 0 0" /></joint><joint name="link_166_to_link_167" type="continuous"><parent link="link_166" /><child link="link_167" /><origin xyz="0 0 2" /><xyz xyz="1 0 0" /></joint><joint name="link_167_to_link_168" type="continuous"><parent link="link_167" /><child link="link_168" /><origin xyz="0 0 2" /><xyz xyz="1 0 0" /></joint><joint name="link_168_to_link_169" type="continuous"><parent link="link_168" /><child link="link_169" /><origin xyz="0 0 2" /><xyz xyz="1 0 0" /></joint><joint name="link_169_to_link_170" type="continuous"><parent link="link_169" /><child link="link_170" /><origin xyz="0 0 2" /><xyz xyz="1 0 0" /></joint><joint name="link_170_to_link_171" type="continuous"><parent link="link_170" /><child link="link_171" /><origin xyz="0 0 2" /><xyz xyz="1 0 0" /></joint><joint name="link_171_to_link_172" type="continuous"><parent link="link_171" /><child link="link_172" /><origin xyz="0 0 2" /><xyz xyz="1 0 0" /></joint><joint name="link_172_to_link_173" type="continuous"><parent link="link_172" /><child link="link_173" /><origin xyz="0 0 2" /><xyz xyz="1 0 0" /></joint><joint name="link_173_to_link_174" type="continuous"><parent link="link_173" /><child link="link_174" /><origin xyz="0 0 2" /><xyz xyz="1 0 0" /></joint><joint name="link_174_to_link_175" type="continuous"><parent link="link_174" /><child link="link_175" /><origin xyz="0 0 2" /><xyz xyz="1 0 0" /></joint><joint name="link_175_to_link_176" type="continuous"><parent link="link_175" /><child link="link_176" /><origin xyz="0 0 2" /><xyz xyz="1 0 0" /></joint><joint name="link_176_to_link_177" type="continuous"><parent link="link_176" /><child link="link_177" /><origin xyz="0 0 2" /><xyz xyz="1 0 0" /></joint><joint name="link_177_to_link_178" type="continuous"><parent link="link_177" /><child link="link_178" /><origin xyz="0 0 2" /><xyz xyz="1 0 0" /></joint><joint name="link_178_to_link_179" type="continuous"><parent link="link_178" /><child link="link_179" /><origin xyz="0 0 2" /><xyz xyz="1 0 0" /></joint><joint name="link_179_to_link_180" type="continuous"><parent link="link_179" /><child link="link_180" /><origin xyz="0 0 2" /><xyz xyz="1 0 0" /></joint><joint name="link_180_to_link_181" type="continuous"><parent link="link_180" /><child link="link_181" /><origin xyz="0 0 2" /><xyz xyz="1 0 0" /></joint><joint name="link_181_to_link_182" type="continuous"><parent link="link_181" /><child link="link_182" /><origin xyz="0 0 2" /><xyz xyz="1 0 0" /></joint><joint name="link_182_to_link_183" type="continuous"><parent link="link_182" /><child link="link_183" /><origin xyz="0 0 2" /><xyz xyz="1 0 0" /></joint><joint name="link_183_to_link_184" type="continuous"><parent link="link_183" /><child link="link_184" /><origin xyz="0 0 2" /><xyz xyz="1 0 0" /></joint><joint name="link_184_to_link_185" type="continuous"><parent link="link_184" /><child link="link_185" /><origin xyz="0 0 2" /><xyz xyz="1 0 0" /></joint><joint name="link_185_to_link_186" type="continuous"><parent link="link_185" /><child link="link_186" /><origin xyz="0 0 2" /><xyz xyz="1 0 0" /></joint><joint name="link_186_to_link_187" type="continuous"><parent link="link_186" /><child link="link_187" /><origin xyz="0 0 2" /><xyz xyz="1 0 0" /></joint><joint name="link_187_to_link_188" type="continuous"><parent link="link_187" /><child link="link_188" /><origin xyz="0 0 2" /><xyz xyz="1 0 0" /></joint><joint name="link_188_to_link_189" type="continuous"><parent link="link_188" /><child link="link_189" /><origin xyz="0 0 2" /><xyz xyz="1 0 0" /></joint><joint name="link_189_to_link_190" type="continuous"><parent link="link_189" /><child link="link_190" /><origin xyz="0 0 2" /><xyz xyz="1 0 0" /></joint><joint name="link_190_to_link_191" type="continuous"><parent link="link_190" /><child link="link_191" /><origin xyz="0 0 2" /><xyz xyz="1 0 0" /></joint><joint name="link_191_to_link_192" type="continuous"><parent link="link_191" /><child link="link_192" /><origin xyz="0 0 2" /><xyz xyz="1 0 0" /></joint><joint name="link_192_to_link_193" type="continuous"><parent link="link_192" /><child link="link_193" /><origin xyz="0 0 2" /><xyz xyz="1 0 0" /></joint><joint name="link_193_to_link_194" type="continuous"><parent link="link_193" /><child link="link_194" /><origin xyz="0 0 2" /><xyz xyz="1 0 0" /></joint><joint name="link_194_to_link_195" type="continuous"><parent link="link_194" /><child link="link_195" /><origin xyz="0 0 2" /><xyz xyz="1 0 0" /></joint><joint name="link_195_to_link_196" type="continuous"><parent link="link_195" /><child link="link_196" /><origin xyz="0 0 2" /><xyz xyz="1 0 0" /></joint><joint name="link_196_to_link_197" type="continuous"><parent link="link_196" /><child link="link_197" /><origin xyz="0 0 2" /><xyz xyz="1 0 0" /></joint><joint name="link_197_to_link_198" type="continuous"><parent link="link_197" /><child link="link_198" /><origin xyz="0 0 2" /><xyz xyz="1 0 0" /></joint><joint name="link_198_to_link_199" type="continuous"><parent link="link_198" /><child link="link_199" /><origin xyz="0 0 2" /><xyz xyz="1 0 0" /></joint><joint name="link_199_to_link_200" type="continuous"><parent link="link_199" /><child link="link_200" /><origin xyz="0 0 2" /><xyz xyz="1 0 0" /></joint><joint name="link_200_to_link_201" type="continuous"><parent link="link_200" /><child link="link_201" /><origin xyz="0 0 2" /><xyz xyz="1 0 0" /></joint><joint name="link_201_to_link_202" type="continuous"><parent link="link_201" /><child link="link_202" /><origin xyz="0 0 2" /><xyz xyz="1 0 0" /></joint><joint name="link_202_to_link_203" type="continuous"><parent link="link_202" /><child link="link_203" /><origin xyz="0 0 2" /><xyz xyz="1 0 0" /></joint><joint name="link_203_to_link_204" type="continuous"><parent link="link_203" /><child link="link_204" /><origin xyz="0 0 2" /><xyz xyz="1 0 0" /></joint><joint name="link_204_to_link_205" type="continuous"><parent link="link_204" /><child link="link_205" /><origin xyz="0 0 2" /><xyz xyz="1 0 0" /></joint><joint name="link_205_to_link_206" type="continuous"><parent link="link_205" /><child link="link_206" /><origin xyz="0 0 2" /><xyz xyz="1 0 0" /></joint><joint name="link_206_to_link_207" type="continuous"><parent link="link_206" /><child link="link_207" /><origin xyz="0 0 2" /><xyz xyz="1 0 0" /></joint><joint name="link_207_to_link_208" type="continuous"><parent link="link_207" /><child link="link_208" /><origin xyz="0 0 2" /><xyz xyz="1 0 0" /></joint><joint name="link_208_to_link_209" type="continuous"><parent link="link_208" /><child link="link_209" /><origin xyz="0 0 2" /><xyz xyz="1 0 0" /></joint><joint name="link_209_to_link_210" type="continuous"><parent link="link_209" /><child link="link_210" /><origin xyz="0 0 2" /><xyz xyz="1 0 0" /></joint><joint name="link_210_to_link_211" type="continuous"><parent link="link_210" /><child link="link_211" /><origin xyz="0 0 2" /><xyz xyz="1 0 0" /></joint><joint name="link_211_to_link_212" type="continuous"><parent link="link_211" /><child link="link_212" /><origin xyz="0 0 2" /><xyz xyz="1 0 0" /></joint><joint name="link_212_to_link_213" type="continuous"><parent link="link_212" /><child link="link_213" /><origin xyz="0 0 2" /><xyz xyz="1 0 0" /></joint><joint name="link_213_to_link_214" type="continuous"><parent link="link_213" /><child link="link_214" /><origin xyz="0 0 2" /><xyz xyz="1 0 0" /></joint><joint name="link_214_to_link_215" type="continuous"><parent link="link_214" /><child link="link_215" /><origin xyz="0 0 2" /><xyz xyz="1 0 0" /></joint><joint name="link_215_to_link_216" type="continuous"><parent link="link_215" /><child link="link_216" /><origin xyz="0 0 2" /><xyz xyz="1 0 0" /></joint><joint name="link_216_to_link_217" type="continuous"><parent link="link_216" /><child link="link_217" /><origin xyz="0 0 2" /><xyz xyz="1 0 0" /></joint><joint name="link_217_to_link_218" type="continuous"><parent link="link_217" /><child link="link_218" /><origin xyz="0 0 2" /><xyz xyz="1 0 0" /></joint><joint name="link_218_to_link_219" type="continuous"><parent link="link_218" /><child link="link_219" /><origin xyz="0 0 2" /><xyz xyz="1 0 0" /></joint><joint name="link_219_to_link_220" type="continuous"><parent link="link_219" /><child link="link_220" /><origin xyz="0 0 2" /><xyz xyz="1 0 0" /></joint><joint name="link_220_to_link_221" type="continuous"><parent link="link_220" /><child link="link_221" /><origin xyz="0 0 2" /><xyz xyz="1 0 0" /></joint><joint name="link_221_to_link_222" type="continuous"><parent link="link_221" /><child link="link_222" /><origin xyz="0 0 2" /><xyz xyz="1 0 0" /></joint><joint name="link_222_to_link_223" type="continuous"><parent link="link_222" /><child link="link_223" /><origin xyz="0 0 2" /><xyz xyz="1 0 0" /></joint><joint name="link_223_to_link_224" type="continuous"><parent link="link_223" /><child link="link_224" /><origin xyz="0 0 2" /><xyz xyz="1 0 0" /></joint><joint name="link_224_to_link_225" type="continuous"><parent link="link_224" /><child link="link_225" /><origin xyz="0 0 2" /><xyz xyz="1 0 0" /></joint><joint name="link_225_to_link_226" type="continuous"><parent link="link_225" /><child link="link_226" /><origin xyz="0 0 2" /><xyz xyz="1 0 0" /></joint><joint name="link_226_to_link_227" type="continuous"><parent link="link_226" /><child link="link_227" /><origin xyz="0 0 2" /><xyz xyz="1 0 0" /></joint><joint name="link_227_to_link_228" type="continuous"><parent link="link_227" /><child link="link_228" /><origin xyz="0 0 2" /><xyz xyz="1 0 0" /></joint><joint name="link_228_to_link_229" type="continuous"><parent link="link_228" /><child link="link_229" /><origin xyz="0 0 2" /><xyz xyz="1 0 0" /></joint><joint name="link_229_to_link_230" type="continuous"><parent link="link_229" /><child link="link_230" /><origin xyz="0 0 2" /><xyz xyz="1 0 0" /></joint><joint name="link_230_to_link_231" type="continuous"><parent link="link_230" /><child link="link_231" /><origin xyz="0 0 2" /><xyz xyz="1 0 0" /></joint><joint name="link_231_to_link_232" type="continuous"><parent link="link_231" /><child link="link_232" /><origin xyz="0 0 2" /><xyz xyz="1 0 0" /></joint><joint name="link_232_to_link_233" type="continuous"><parent link="link_232" /><child link="link_233" /><origin xyz="0 0 2" /><xyz xyz="1 0 0" /></joint><joint name="link_233_to_link_234" type="continuous"><parent link="link_233" /><child link="link_234" /><origin xyz="0 0 2" /><xyz xyz="1 0 0" /></joint></robot>