<robot name="plane">
  <link name="link_0">
  <contact>
      <lateral_friction value="1" />
  </contact>
    <inertial>
      <origin rpy="0 0 0" xyz="0 0 0" />
       <mass value=".0" />
       <inertia ixx="0" ixy="0" ixz="0" iyy="0" iyz="0" izz="0" />
    </inertial>
    <visual>
      <origin rpy="0 0 0" xyz="0 0 0" />
      <geometry>
          <mesh filename="plane.obj" scale="1 1 1" />
      </geometry>
       <material name="white">
        <color rgba="1 1 1 1" />
      </material>
    </visual>
    <collision>
      <origin rpy="0 0 0" xyz="0 0 -5" />
      <geometry>
                <box size="30 30 10" />
      </geometry>
    </collision>
  </link>




<link name="link_1"><collision><geometry><cylinder length="0.6" radius="0.2" /></geometry><origin xyz ="0 0 1" /></collision></link>
<link name="link_2"><collision><geometry><cylinder length="0.6" radius="0.2" /></geometry><origin xyz ="0 0 1" /></collision></link>
<link name="link_3"><collision><geometry><cylinder length="0.6" radius="0.2" /></geometry><origin xyz ="0 0 1" /></collision></link>
<link name="link_4"><collision><geometry><cylinder length="0.6" radius="0.2" /></geometry><origin xyz ="0 0 1" /></collision></link>
<joint name="link_0_to_link_1" type="continuous"><parent link="link_0" /><child link="link_1" /><origin  xyz="0 0 2" /><xyz xyz="1 0 0" /></joint>
<joint name="link_1_to_link_2" type="continuous"><parent link="link_1" /><child link="link_2" /><origin  xyz="0 0 2" /><axis xyz="1 0 0" /></joint>
<joint name="link_2_to_link_3" type="continuous"><parent link="link_2" /><child link="link_3" /><origin  xyz="0 0 2" /><axis xyz="1 0 0" /></joint>
<joint name="link_3_to_link_4" type="continuous"><parent link="link_3" /><child link="link_4" /><origin  xyz="0 0 2" /><axis xyz="1 0 0" /></joint>

</robot>
